Workbook

Sheet 1AS 1B
A1: COLEGIOELROBLE | L1: Fecha: | N1: 09/12/2025
A2: CUBICOL Intranet | L2: Hora: | N2: 12:29:56
A3: CONSOLIDADO DE NOTAS - 2025
A5: Salón: | C5: 1ER AÑO A SECUNDARIA | D5: Periodo: | F5: 1er Bimestre | I5: Tutor: | K5: OLIVARES COELLO, Edilberto
A6: ASIGNATURAS | D6: COMUNICACIÓN | E6: Lenguaje | F6: Literatura | G6: Plan Lector | H6: Raz. Verbal | I6: MATEMÁTICAS | J6: Álgebra | K6: Aritmética | L6: Geometría | M6: Raz. Matemático | N6: Trigonometría | O6: CIENCIA Y TECNOLOGÍA | P6: Biología | Q6: Física | R6: Química | S6: CIENCIAS SOCIALES | T6: Geografía | U6: Historia del Perú | V6: Historia Universal | W6: EDUCACIÓN PARA EL TRABAJO | X6: Computación | Y6: ARTE Y CULTURA | Z6: DESARROLLO PERSONAL Y CIUDADANA CÍVICA | AA6: EDUCACIÓN FISICA | AB6: INGLES | AC6: CONDUCTA | AD6: PROMEDIO | AE6: PUNTAJE | AF6: N° DESAPROBADOS | AG6: ORDEN DE MÉRITO | AH6: TERCIO | AI6: Tardanza Injustificada | AJ6: Tardanza Justificada | AK6: Falta Injustificada | AL6: Falta Justificada
A7: N° | B7: APELLIDOS Y NOMBRES
A8: 1 | B8: ALBINO CONDORI, Andre Anderson | D8: 16 | E8: 15 | F8: 16 | G8: 18 | H8: 16 | I8: 14 | J8: 13 | K8: 14 | L8: 16 | M8: 14 | N8: 15 | O8: 16 | P8: 17 | Q8: 14 | R8: 16 | S8: 13 | T8: 16 | U8: 11 | V8: 11 | W8: 16 | X8: 16 | Y8: 16 | Z8: 15 | AA8: 17 | AB8: 16 | AD8: 15.44 | AE8: 139 | AG8: 13 | AH8: MED | AI8: 5 | AM8: =AE8+'1AS 2B'!AE8+'1AS 3B'!AE8+'1AS 4B'!AE8 -> 531 | AN8: =RANK(AM8,$AM$8:$AM$32, ) -> 15
A9: 2 | B9: ALVARADO ACOSTA, Debora Abigail | D9: 17 | E9: 15 | F9: 19 | G9: 17 | H9: 16 | I9: 16 | J9: 16 | K9: 14 | L9: 16 | M9: 17 | N9: 15 | O9: 17 | P9: 17 | Q9: 15 | R9: 18 | S9: 14 | T9: 16 | U9: 13 | V9: 12 | W9: 16 | X9: 16 | Y9: 15 | Z9: 14 | AA9: 17 | AB9: 16 | AD9: 15.78 | AE9: 142 | AG9: 12 | AH9: MED | AI9: 4 | AM9: =AE9+'1AS 2B'!AE9+'1AS 3B'!AE9+'1AS 4B'!AE9 -> 558 | AN9: =RANK(AM9,$AM$8:$AM$32, ) -> 9
A10: 3 | B10: BENITES ACOSTA, Cielo Guadalupe | D10: 15 | E10: 15 | F10: 14 | G10: 17 | H10: 15 | I10: 14 | J10: 14 | K10: 13 | L10: 15 | M10: 15 | N10: 15 | O10: 13 | P10: 15 | Q10: 13 | R10: 10 | S10: 13 | T10: 12 | U10: 13 | V10: 13 | W10: 16 | X10: 16 | Y10: 15 | Z10: 12 | AA10: 16 | AB10: 15 | AD10: 14.33 | AE10: 129 | AG10: 23 | AH10: INF | AM10: =AE10+'1AS 2B'!AE10+'1AS 3B'!AE10+'1AS 4B'!AE10 -> 490 | AN10: =RANK(AM10,$AM$8:$AM$32, ) -> 25
A11: 4 | B11: CABANILLAS HUAYLLAHUA | D11: 17 | E11: 16 | F11: 17 | G11: 17 | H11: 16 | I11: 16 | J11: 15 | K11: 15 | L11: 17 | M11: 16 | N11: 16 | O11: 16 | P11: 18 | Q11: 15 | R11: 15 | S11: 14 | T11: 16 | U11: 13 | V11: 14 | W11: 16 | X11: 16 | Y11: 17 | Z11: 14 | AA11: 17 | AB11: 16 | AD11: 15.89 | AE11: 143 | AG11: 8 | AH11: SUP | AI11: 1 | AM11: =AE11+'1AS 2B'!AE11+'1AS 3B'!AE11+'1AS 4B'!AE11 -> 555 | AN11: =RANK(AM11,$AM$8:$AM$32, ) -> 11
A12: 5 | B12: CENTENO TARAZONA, Camila Adriana | D12: 16 | E12: 14 | F12: 16 | G12: 17 | H12: 16 | I12: 16 | J12: 15 | K12: 16 | L12: 17 | M12: 17 | N12: 16 | O12: 16 | P12: 18 | Q12: 15 | R12: 15 | S12: 15 | T12: 17 | U12: 14 | V12: 14 | W12: 16 | X12: 16 | Y12: 17 | Z12: 16 | AA12: 17 | AB12: 16 | AD12: 16.11 | AE12: 145 | AG12: 5 | AH12: SUP | AM12: =AE12+'1AS 2B'!AE12+'1AS 3B'!AE12+'1AS 4B'!AE12 -> 578 | AN12: =RANK(AM12,$AM$8:$AM$32, ) -> 5
A13: 6 | B13: CHAHUARES HUAMANI, Lucero Andrea | D13: 16 | E13: 14 | F13: 17 | G13: 17 | H13: 15 | I13: 15 | J13: 15 | K13: 15 | L13: 16 | M13: 15 | N13: 15 | O13: 16 | P13: 17 | Q13: 16 | R13: 14 | S13: 14 | T13: 16 | U13: 13 | V13: 12 | W13: 16 | X13: 16 | Y13: 17 | Z13: 15 | AA13: 17 | AB13: 17 | AD13: 15.89 | AE13: 143 | AG13: 8 | AH13: SUP | AI13: 1 | AM13: =AE13+'1AS 2B'!AE13+'1AS 3B'!AE13+'1AS 4B'!AE13 -> 562 | AN13: =RANK(AM13,$AM$8:$AM$32, ) -> 8
A14: 7 | B14: DURAND CRUZADO, Christian Gabriel | D14: 16 | E14: 15 | F14: 16 | G14: 18 | H14: 16 | I14: 14 | J14: 14 | K14: 13 | L14: 15 | M14: 14 | N14: 15 | O14: 14 | P14: 16 | Q14: 14 | R14: 12 | S14: 12 | T14: 14 | U14: 11 | V14: 12 | W14: 16 | X14: 16 | Y14: 16 | Z14: 15 | AA14: 17 | AB14: 16 | AD14: 15.11 | AE14: 136 | AG14: 17 | AH14: INF | AM14: =AE14+'1AS 2B'!AE14+'1AS 3B'!AE14+'1AS 4B'!AE14 -> 520 | AN14: =RANK(AM14,$AM$8:$AM$32, ) -> 17
A15: 8 | B15: FIGUEROA PALOMINO, Yanely Nicol | D15: 16 | E15: 15 | F15: 16 | G15: 18 | H15: 16 | I15: 16 | J15: 15 | K15: 15 | L15: 16 | M15: 16 | N15: 16 | O15: 16 | P15: 17 | Q15: 16 | R15: 15 | S15: 14 | T15: 16 | U15: 13 | V15: 13 | W15: 17 | X15: 17 | Y15: 17 | Z15: 15 | AA15: 16 | AB15: 16 | AD15: 15.89 | AE15: 143 | AG15: 8 | AH15: SUP | AM15: =AE15+'1AS 2B'!AE15+'1AS 3B'!AE15+'1AS 4B'!AE15 -> 557 | AN15: =RANK(AM15,$AM$8:$AM$32, ) -> 10
A16: 9 | B16: FRANCISCO RAMIREZ, Lucero Kasumy | D16: 15 | E16: 16 | F16: 14 | G16: 16 | H16: 15 | I16: 15 | J16: 15 | K16: 15 | L16: 16 | M16: 15 | N16: 15 | O16: 16 | P16: 16 | Q16: 15 | R16: 16 | S16: 14 | T16: 15 | U16: 13 | V16: 13 | W16: 15 | X16: 15 | Y16: 15 | Z16: 14 | AA16: 17 | AB16: 16 | AD16: 15.22 | AE16: 137 | AG16: 15 | AH16: MED | AI16: 3 | AM16: =AE16+'1AS 2B'!AE16+'1AS 3B'!AE16+'1AS 4B'!AE16 -> 515 | AN16: =RANK(AM16,$AM$8:$AM$32, ) -> 19
A17: 10 | B17: GUTIERREZ SANCHEZ, Joshua David | D17: 17 | E17: 15 | F17: 19 | G17: 18 | H17: 16 | I17: 17 | J17: 14 | K17: 17 | L17: 18 | M17: 16 | N17: 18 | O17: 17 | P17: 17 | Q17: 17 | R17: 18 | S17: 15 | T17: 18 | U17: 14 | V17: 14 | W17: 16 | X17: 16 | Y17: 17 | Z17: 15 | AA17: 17 | AB17: 17 | AD17: 16.44 | AE17: 148 | AG17: 3 | AH17: SUP | AI17: 5 | AM17: =AE17+'1AS 2B'!AE17+'1AS 3B'!AE17+'1AS 4B'!AE17 -> 591 | AN17: =RANK(AM17,$AM$8:$AM$32, ) -> 3
A18: 11 | B18: JAIMES VILLADEZA, Mari Meredid | D18: 16 | E18: 15 | F18: 16 | G18: 16 | H18: 16 | I18: 15 | J18: 14 | K18: 15 | L18: 15 | M18: 15 | N18: 15 | O18: 15 | P18: 16 | Q18: 15 | R18: 13 | S18: 15 | T18: 17 | U18: 14 | V18: 14 | W18: 16 | X18: 16 | Y18: 17 | Z18: 17 | AA18: 16 | AB18: 16 | AD18: 15.89 | AE18: 143 | AG18: 8 | AH18: SUP | AI18: 1 | AM18: =AE18+'1AS 2B'!AE18+'1AS 3B'!AE18+'1AS 4B'!AE18 -> 552 | AN18: =RANK(AM18,$AM$8:$AM$32, ) -> 12
A19: 12 | B19: JAVES CASTRO, Yaretzy Valeria Anahid | D19: 16 | E19: 15 | F19: 13 | G19: 18 | H19: 16 | I19: 15 | J19: 15 | K19: 14 | L19: 15 | M19: 16 | N19: 15 | O19: 15 | P19: 17 | Q19: 15 | R19: 13 | S19: 14 | T19: 15 | U19: 14 | V19: 13 | W19: 16 | X19: 16 | Y19: 15 | Z19: 14 | AA19: 17 | AB19: 16 | AD19: 15.33 | AE19: 138 | AG19: 14 | AH19: MED | AI19: 6 | AM19: =AE19+'1AS 2B'!AE19+'1AS 3B'!AE19+'1AS 4B'!AE19 -> 533 | AN19: =RANK(AM19,$AM$8:$AM$32, ) -> 14
A20: 13 | B20: MORI ANDRADE, Juan Diego | D20: 15 | E20: 14 | F20: 15 | G20: 16 | H20: 16 | I20: 15 | J20: 13 | K20: 14 | L20: 16 | M20: 15 | N20: 15 | O20: 15 | P20: 15 | Q20: 13 | R20: 16 | S20: 13 | T20: 13 | U20: 15 | V20: 11 | W20: 15 | X20: 15 | Y20: 14 | Z20: 13 | AA20: 17 | AB20: 17 | AD20: 14.89 | AE20: 134 | AG20: 19 | AH20: INF | AM20: =AE20+'1AS 2B'!AE20+'1AS 3B'!AE20+'1AS 4B'!AE20 -> 510 | AN20: =RANK(AM20,$AM$8:$AM$32, ) -> 20
A21: 14 | B21: NANFUÑAY LLUEN, Gerson David | D21: 17 | E21: 16 | F21: 19 | G21: 18 | H21: 15 | I21: 18 | J21: 17 | K21: 18 | L21: 18 | M21: 18 | N21: 18 | O21: 18 | P21: 18 | Q21: 17 | R21: 19 | S21: 15 | T21: 17 | U21: 13 | V21: 14 | W21: 16 | X21: 16 | Y21: 18 | Z21: 16 | AA21: 16 | AB21: 16 | AD21: 16.67 | AE21: 150 | AG21: 2 | AH21: SUP | AI21: 1 | AM21: =AE21+'1AS 2B'!AE21+'1AS 3B'!AE21+'1AS 4B'!AE21 -> 624 | AN21: =RANK(AM21,$AM$8:$AM$32, ) -> 1
A22: 15 | B22: NINAQUISPE AYALA, Dayron Yahir | D22: 16 | E22: 14 | F22: 16 | G22: 16 | H22: 16 | I22: 15 | J22: 14 | K22: 14 | L22: 16 | M22: 15 | N22: 14 | O22: 15 | P22: 17 | Q22: 14 | R22: 15 | S22: 13 | T22: 13 | U22: 13 | V22: 12 | W22: 15 | X22: 15 | Y22: 15 | Z22: 13 | AA22: 17 | AB22: 17 | AD22: 15.11 | AE22: 136 | AG22: 17 | AH22: INF | AI22: 1 | AM22: =AE22+'1AS 2B'!AE22+'1AS 3B'!AE22+'1AS 4B'!AE22 -> 520 | AN22: =RANK(AM22,$AM$8:$AM$32, ) -> 17
A23: 16 | B23: PASACHE HONORES, Martin Nicolas | D23: 16 | E23: 15 | F23: 15 | G23: 16 | H23: 16 | I23: 16 | J23: 16 | K23: 17 | L23: 16 | M23: 16 | N23: 16 | O23: 17 | P23: 17 | Q23: 16 | R23: 19 | S23: 14 | T23: 16 | U23: 12 | V23: 13 | W23: 15 | X23: 15 | Y23: 18 | Z23: 16 | AA23: 17 | AB23: 17 | AD23: 16.22 | AE23: 146 | AG23: 4 | AH23: SUP | AM23: =AE23+'1AS 2B'!AE23+'1AS 3B'!AE23+'1AS 4B'!AE23 -> 575 | AN23: =RANK(AM23,$AM$8:$AM$32, ) -> 7
A24: 17 | B24: PEREZ GOMEZ, Ashley Sara | D24: 15 | E24: 15 | F24: 12 | G24: 16 | H24: 15 | I24: 14 | J24: 13 | K24: 12 | L24: 14 | M24: 14 | N24: 15 | O24: 14 | P24: 15 | Q24: 13 | R24: 14 | S24: 12 | T24: 14 | U24: 11 | V24: 11 | W24: 15 | X24: 15 | Y24: 14 | Z24: 12 | AA24: 16 | AB24: 15 | AD24: 14.11 | AE24: 127 | AG24: 25 | AH24: INF | AI24: 1 | AM24: =AE24+'1AS 2B'!AE24+'1AS 3B'!AE24+'1AS 4B'!AE24 -> 497 | AN24: =RANK(AM24,$AM$8:$AM$32, ) -> 24
A25: 18 | B25: RAMOS MELENDEZ, Aaron Pablo Wiliam | D25: 15 | E25: 14 | F25: 15 | G25: 15 | H25: 15 | I25: 14 | J25: 14 | K25: 13 | L25: 14 | M25: 15 | N25: 14 | O25: 14 | P25: 16 | Q25: 13 | R25: 13 | S25: 13 | T25: 14 | U25: 13 | V25: 13 | W25: 15 | X25: 15 | Y25: 14 | Z25: 13 | AA25: 17 | AB25: 16 | AD25: 14.56 | AE25: 131 | AG25: 21 | AH25: INF | AM25: =AE25+'1AS 2B'!AE25+'1AS 3B'!AE25+'1AS 4B'!AE25 -> 503 | AN25: =RANK(AM25,$AM$8:$AM$32, ) -> 22
A26: 19 | B26: ROSALES ESPINOZA, Yamila Sayury | D26: 17 | E26: 15 | F26: 17 | G26: 18 | H26: 16 | I26: 16 | J26: 15 | K26: 16 | L26: 15 | M26: 17 | N26: 16 | O26: 17 | P26: 18 | Q26: 16 | R26: 16 | S26: 13 | T26: 16 | U26: 12 | V26: 12 | W26: 16 | X26: 16 | Y26: 17 | Z26: 14 | AA26: 17 | AB26: 17 | AD26: 16 | AE26: 144 | AG26: 7 | AH26: SUP | AM26: =AE26+'1AS 2B'!AE26+'1AS 3B'!AE26+'1AS 4B'!AE26 -> 576 | AN26: =RANK(AM26,$AM$8:$AM$32, ) -> 6
A27: 20 | B27: SANCHEZ ROSALES, Danna Gaela | D27: 15 | E27: 15 | F27: 14 | G27: 16 | H27: 15 | I27: 14 | J27: 13 | K27: 13 | L27: 15 | M27: 14 | N27: 16 | O27: 13 | P27: 15 | Q27: 13 | R27: 12 | S27: 13 | T27: 13 | U27: 13 | V27: 12 | W27: 16 | X27: 16 | Y27: 15 | Z27: 13 | AA27: 17 | AB27: 15 | AD27: 14.56 | AE27: 131 | AG27: 21 | AH27: INF | AM27: =AE27+'1AS 2B'!AE27+'1AS 3B'!AE27+'1AS 4B'!AE27 -> 509 | AN27: =RANK(AM27,$AM$8:$AM$32, ) -> 21
A28: 21 | B28: USCAMAYTA CRISTOBAL, Cristobal Belinda | D28: 17 | E28: 15 | F28: 18 | G28: 18 | H28: 15 | I28: 17 | J28: 15 | K28: 17 | L28: 17 | M28: 17 | N28: 17 | O28: 17 | P28: 18 | Q28: 16 | R28: 17 | S28: 14 | T28: 17 | U28: 13 | V28: 13 | W28: 16 | X28: 16 | Y28: 17 | Z28: 15 | AA28: 16 | AB28: 16 | AD28: 16.11 | AE28: 145 | AG28: 5 | AH28: SUP | AM28: =AE28+'1AS 2B'!AE28+'1AS 3B'!AE28+'1AS 4B'!AE28 -> 581 | AN28: =RANK(AM28,$AM$8:$AM$32, ) -> 4
A29: 22 | B29: VALCARCEL DIAZ, Sihana Arabela | D29: 16 | E29: 16 | F29: 15 | G29: 16 | H29: 16 | I29: 14 | J29: 13 | K29: 13 | L29: 13 | M29: 14 | N29: 15 | O29: 14 | P29: 15 | Q29: 14 | R29: 13 | S29: 13 | T29: 14 | U29: 12 | V29: 13 | W29: 16 | X29: 16 | Y29: 14 | Z29: 14 | AA29: 17 | AB29: 14 | AD29: 14.67 | AE29: 132 | AG29: 20 | AH29: INF | AM29: =AE29+'1AS 2B'!AE29+'1AS 3B'!AE29+'1AS 4B'!AE29 -> 523 | AN29: =RANK(AM29,$AM$8:$AM$32, ) -> 16
A30: 23 | B30: VARGAS VASQUEZ, Ayalen Danae | D30: 17 | E30: 16 | F30: 18 | G30: 18 | H30: 16 | I30: 19 | J30: 19 | K30: 19 | L30: 18 | M30: 19 | N30: 18 | O30: 19 | P30: 19 | Q30: 18 | R30: 19 | S30: 14 | T30: 16 | U30: 12 | V30: 15 | W30: 16 | X30: 16 | Y30: 19 | Z30: 17 | AA30: 17 | AB30: 17 | AD30: 17.22 | AE30: 155 | AG30: 1 | AH30: SUP | AI30: 1 | AM30: =AE30+'1AS 2B'!AE30+'1AS 3B'!AE30+'1AS 4B'!AE30 -> 613 | AN30: =RANK(AM30,$AM$8:$AM$32, ) -> 2
A31: 24 | B31: VASQUEZ TAIÑA, Isaac Adriel | D31: 15 | E31: 15 | F31: 13 | G31: 17 | H31: 16 | I31: 17 | J31: 15 | K31: 17 | L31: 18 | M31: 16 | N31: 17 | O31: 16 | P31: 16 | Q31: 14 | R31: 17 | S31: 13 | T31: 15 | U31: 12 | V31: 13 | W31: 15 | X31: 15 | Y31: 13 | Z31: 15 | AA31: 17 | AB31: 16 | AD31: 15.22 | AE31: 137 | AG31: 15 | AH31: MED | AM31: =AE31+'1AS 2B'!AE31+'1AS 3B'!AE31+'1AS 4B'!AE31 -> 550 | AN31: =RANK(AM31,$AM$8:$AM$32, ) -> 13
A32: 25 | B32: VEGA GUISASOLA, Lennyn | D32: 16 | E32: 15 | F32: 17 | G32: 14 | H32: 16 | I32: 15 | J32: 15 | K32: 13 | L32: 16 | M32: 16 | N32: 15 | O32: 15 | P32: 17 | Q32: 13 | R32: 16 | S32: 13 | T32: 15 | U32: 12 | V32: 12 | W32: 14 | X32: 14 | Y32: 13 | Z32: 12 | AA32: 16 | AB32: 14 | AD32: 14.22 | AE32: 128 | AG32: 24 | AH32: INF | AI32: 6 | AM32: =AE32+'1AS 2B'!AE32+'1AS 3B'!AE32+'1AS 4B'!AE32 -> 498 | AN32: =RANK(AM32,$AM$8:$AM$32, ) -> 23
B34: Promedio del curso: | D34: 16 | E34: 15 | F34: 15.9 | G34: 16.8 | H34: 15.7 | I34: 15.5 | J34: 14.7 | K34: 14.9 | L34: 15.9 | M34: 15.7 | N34: 15.7 | O34: 15.6 | P34: 16.7 | Q34: 14.8 | R34: 15.2 | S34: 13.6 | T34: 15.2 | U34: 12.8 | V34: 12.8 | W34: 15.7 | X34: 15.7 | Y34: 15.8 | Z34: 14.4 | AA34: 16.7 | AB34: 16
B35: N° de alumnos Aprobados: | D35: 25 | E35: 25 | F35: 25 | G35: 25 | H35: 25 | I35: 25 | J35: 25 | K35: 25 | L35: 25 | M35: 25 | N35: 25 | O35: 25 | P35: 25 | Q35: 25 | R35: 24 | S35: 25 | T35: 25 | U35: 25 | V35: 25 | W35: 25 | X35: 25 | Y35: 25 | Z35: 25 | AA35: 25 | AB35: 25
B36: N° de alumnos Desaprobados: | R36: 1
B37: % de alumnos Aprobados: | D37: 100 | E37: 100 | F37: 100 | G37: 100 | H37: 100 | I37: 100 | J37: 100 | K37: 100 | L37: 100 | M37: 100 | N37: 100 | O37: 100 | P37: 100 | Q37: 100 | R37: 96 | S37: 100 | T37: 100 | U37: 100 | V37: 100 | W37: 100 | X37: 100 | Y37: 100 | Z37: 100 | AA37: 100 | AB37: 100
B38: % de alumnos Desaprobados: | R38: 4
B39: Nota Máxima: | D39: 17 | E39: 16 | F39: 19 | G39: 18 | H39: 16 | I39: 19 | J39: 19 | K39: 19 | L39: 18 | M39: 19 | N39: 18 | O39: 19 | P39: 19 | Q39: 18 | R39: 19 | S39: 15 | T39: 18 | U39: 15 | V39: 15 | W39: 17 | X39: 17 | Y39: 19 | Z39: 17 | AA39: 17 | AB39: 17
B40: Nota Mínima: | D40: 15 | E40: 14 | F40: 12 | G40: 14 | H40: 15 | I40: 14 | J40: 13 | K40: 12 | L40: 13 | M40: 14 | N40: 14 | O40: 13 | P40: 15 | Q40: 13 | R40: 10 | S40: 12 | T40: 12 | U40: 11 | V40: 11 | W40: 14 | X40: 14 | Y40: 13 | Z40: 12 | AA40: 16 | AB40: 14

Sheet 1AS 2B
A1: COLEGIOELROBLE | L1: Fecha: | N1: 09/12/2025
A2: CUBICOL Intranet | L2: Hora: | N2: 12:30:18
A3: CONSOLIDADO DE NOTAS - 2025
A5: Salón: | C5: 1ER AÑO A SECUNDARIA | D5: Periodo: | F5: 2do Bimestre | I5: Tutor: | K5: OLIVARES COELLO, Edilberto
A6: ASIGNATURAS | D6: COMUNICACIÓN | E6: Lenguaje | F6: Literatura | G6: Plan Lector | H6: Raz. Verbal | I6: MATEMÁTICAS | J6: Álgebra | K6: Aritmética | L6: Geometría | M6: Raz. Matemático | N6: Trigonometría | O6: CIENCIA Y TECNOLOGÍA | P6: Biología | Q6: Física | R6: Química | S6: CIENCIAS SOCIALES | T6: Geografía | U6: Historia del Perú | V6: Historia Universal | W6: EDUCACIÓN PARA EL TRABAJO | X6: Computación | Y6: ARTE Y CULTURA | Z6: DESARROLLO PERSONAL Y CIUDADANA CÍVICA | AA6: EDUCACIÓN FISICA | AB6: INGLES | AC6: CONDUCTA | AD6: PROMEDIO | AE6: PUNTAJE | AF6: N° DESAPROBADOS | AG6: ORDEN DE MÉRITO | AH6: TERCIO | AI6: Tardanza Injustificada | AJ6: Tardanza Justificada | AK6: Falta Injustificada | AL6: Falta Justificada
A7: N° | B7: APELLIDOS Y NOMBRES
A8: 1 | B8: ALBINO CONDORI, Andre Anderson | D8: 16 | E8: 16 | F8: 16 | G8: 17 | H8: 15 | I8: 14 | J8: 16 | K8: 13 | L8: 15 | M8: 13 | N8: 14 | O8: 15 | P8: 17 | Q8: 14 | R8: 14 | S8: 14 | T8: 16 | U8: 13 | V8: 12 | W8: 15 | X8: 15 | Y8: 14 | Z8: 14 | AA8: 17 | AB8: 12 | AD8: 14.56 | AE8: 131 | AG8: 15 | AH8: MED | AI8: 19
A9: 2 | B9: ALVARADO ACOSTA, Debora Abigail | D9: 16 | E9: 15 | F9: 17 | G9: 17 | H9: 16 | I9: 15 | J9: 15 | K9: 12 | L9: 15 | M9: 16 | N9: 16 | O9: 16 | P9: 16 | Q9: 15 | R9: 17 | S9: 16 | T9: 17 | U9: 15 | V9: 17 | W9: 15 | X9: 15 | Y9: 14 | Z9: 13 | AA9: 16 | AB9: 15 | AD9: 15.11 | AE9: 136 | AG9: 11 | AH9: MED | AI9: 7
A10: 3 | B10: BENITES ACOSTA, Cielo Guadalupe | D10: 14 | E10: 15 | F10: 12 | G10: 16 | H10: 14 | I10: 13 | J10: 13 | K10: 11 | L10: 15 | M10: 12 | N10: 15 | O10: 13 | P10: 13 | Q10: 12 | R10: 14 | S10: 12 | T10: 13 | U10: 11 | V10: 13 | W10: 15 | X10: 15 | Y10: 13 | Z10: 12 | AA10: 15 | AB10: 12 | AD10: 13.22 | AE10: 119 | AG10: 25 | AH10: INF
A11: 4 | B11: CABANILLAS HUAYLLAHUA | D11: 16 | E11: 15 | F11: 16 | G11: 17 | H11: 15 | I11: 15 | J11: 16 | K11: 15 | L11: 16 | M11: 14 | N11: 16 | O11: 16 | P11: 16 | Q11: 14 | R11: 17 | S11: 15 | T11: 17 | U11: 15 | V11: 13 | W11: 16 | X11: 16 | Y11: 15 | Z11: 13 | AA11: 16 | AB11: 15 | AD11: 15.22 | AE11: 137 | AG11: 10 | AH11: MED | AI11: 2
A12: 5 | B12: CENTENO TARAZONA, Camila Adriana | D12: 15 | E12: 15 | F12: 15 | G12: 17 | H12: 14 | I12: 16 | J12: 18 | K12: 16 | L12: 14 | M12: 14 | N12: 16 | O12: 17 | P12: 17 | Q12: 17 | R12: 17 | S12: 16 | T12: 18 | U12: 15 | V12: 15 | W12: 16 | X12: 16 | Y12: 15 | Z12: 17 | AA12: 17 | AB12: 15 | AD12: 16 | AE12: 144 | AG12: 5 | AH12: SUP | AI12: 2
A13: 6 | B13: CHAHUARES HUAMANI, Lucero Andrea | D13: 16 | E13: 16 | F13: 15 | G13: 18 | H13: 16 | I13: 14 | J13: 15 | K13: 15 | L13: 14 | M13: 12 | N13: 14 | O13: 16 | P13: 16 | Q13: 16 | R13: 17 | S13: 16 | T13: 18 | U13: 15 | V13: 14 | W13: 17 | X13: 17 | Y13: 16 | Z13: 15 | AA13: 16 | AB13: 15 | AD13: 15.67 | AE13: 141 | AG13: 8 | AH13: SUP
A14: 7 | B14: DURAND CRUZADO, Christian Gabriel | D14: 15 | E14: 15 | F14: 12 | G14: 16 | H14: 15 | I14: 14 | J14: 15 | K14: 13 | L14: 14 | M14: 13 | N14: 14 | O14: 15 | P14: 16 | Q14: 14 | R14: 14 | S14: 14 | T14: 14 | U14: 14 | V14: 13 | W14: 15 | X14: 15 | Y14: 14 | Z14: 16 | AA14: 16 | AB14: 13 | AD14: 14.67 | AE14: 132 | AG14: 14 | AH14: MED | AI14: 2
A15: 8 | B15: FIGUEROA PALOMINO, Yanely Nicol | D15: 16 | E15: 16 | F15: 16 | G15: 17 | H15: 14 | I15: 15 | J15: 16 | K15: 15 | L15: 14 | M15: 14 | N15: 17 | O15: 17 | P15: 17 | Q15: 16 | R15: 17 | S15: 15 | T15: 16 | U15: 14 | V15: 15 | W15: 16 | X15: 16 | Y15: 13 | Z15: 14 | AA15: 15 | AB15: 15 | AD15: 15.11 | AE15: 136 | AG15: 11 | AH15: MED | AI15: 1
A16: 9 | B16: FRANCISCO RAMIREZ, Lucero Kasumy | D16: 15 | E16: 16 | F16: 14 | G16: 16 | H16: 14 | I16: 14 | J16: 15 | K16: 13 | L16: 14 | M16: 13 | N16: 14 | O16: 15 | P16: 15 | Q16: 14 | R16: 15 | S16: 14 | T16: 14 | U16: 14 | V16: 13 | W16: 15 | X16: 15 | Y16: 13 | Z16: 13 | AA16: 16 | AB16: 11 | AD16: 14 | AE16: 126 | AG16: 18 | AH16: INF | AI16: 12
A17: 10 | B17: GUTIERREZ SANCHEZ, Joshua David | D17: 17 | E17: 16 | F17: 18 | G17: 17 | H17: 15 | I17: 18 | J17: 18 | K17: 19 | L17: 17 | M17: 18 | N17: 18 | O17: 18 | P17: 17 | Q17: 16 | R17: 20 | S17: 17 | T17: 18 | U17: 16 | V17: 17 | W17: 14 | X17: 14 | Y17: 17 | Z17: 15 | AA17: 15 | AB17: 17 | AD17: 16.44 | AE17: 148 | AG17: 3 | AH17: SUP | AI17: 8
A18: 11 | B18: JAIMES VILLADEZA, Mari Meredid | D18: 16 | E18: 15 | F18: 15 | G18: 17 | H18: 15 | I18: 14 | J18: 15 | K18: 16 | L18: 14 | M18: 13 | N18: 14 | O18: 16 | P18: 16 | Q18: 16 | R18: 15 | S18: 15 | T18: 16 | U18: 14 | V18: 15 | W18: 15 | X18: 15 | Y18: 17 | Z18: 17 | AA18: 16 | AB18: 14 | AD18: 15.56 | AE18: 140 | AG18: 9 | AH18: MED | AI18: 2
A19: 12 | B19: JAVES CASTRO, Yaretzy Valeria Anahid | D19: 16 | E19: 15 | F19: 19 | G19: 16 | H19: 15 | I19: 14 | J19: 15 | K19: 12 | L19: 14 | M19: 15 | N19: 15 | O19: 14 | P19: 14 | Q19: 14 | R19: 14 | S19: 15 | T19: 17 | U19: 14 | V19: 13 | W19: 15 | X19: 15 | Y19: 15 | Z19: 14 | AA19: 16 | AB19: 12 | AD19: 14.56 | AE19: 131 | AG19: 15 | AH19: MED | AI19: 12
A20: 13 | B20: MORI ANDRADE, Juan Diego | D20: 15 | E20: 14 | F20: 16 | G20: 15 | H20: 16 | I20: 12 | J20: 12 | K20: 10 | L20: 14 | M20: 12 | N20: 14 | O20: 13 | P20: 16 | Q20: 10 | R20: 14 | S20: 13 | T20: 14 | U20: 12 | V20: 13 | W20: 14 | X20: 14 | Y20: 12 | Z20: 13 | AA20: 16 | AB20: 12 | AD20: 13.33 | AE20: 120 | AG20: 23 | AH20: INF | AI20: 1
A21: 14 | B21: NANFUÑAY LLUEN, Gerson David | D21: 16 | E21: 17 | F21: 17 | G21: 17 | H21: 14 | I21: 19 | J21: 18 | K21: 20 | L21: 19 | M21: 19 | N21: 19 | O21: 19 | P21: 17 | Q21: 19 | R21: 20 | S21: 17 | T21: 18 | U21: 17 | V21: 16 | W21: 16 | X21: 16 | Y21: 18 | Z21: 17 | AA21: 17 | AB21: 19 | AD21: 17.56 | AE21: 158 | AG21: 1 | AH21: SUP
A22: 15 | B22: NINAQUISPE AYALA, Dayron Yahir | D22: 15 | E22: 15 | F22: 14 | G22: 16 | H22: 14 | I22: 13 | J22: 13 | K22: 11 | L22: 15 | M22: 13 | N22: 14 | O22: 13 | P22: 16 | Q22: 11 | R22: 13 | S22: 13 | T22: 15 | U22: 14 | V22: 11 | W22: 16 | X22: 16 | Y22: 11 | Z22: 13 | AA22: 17 | AB22: 12 | AD22: 13.67 | AE22: 123 | AG22: 20 | AH22: INF
A23: 16 | B23: PASACHE HONORES, Martin Nicolas | D23: 15 | E23: 15 | F23: 16 | G23: 16 | H23: 14 | I23: 16 | J23: 15 | K23: 17 | L23: 16 | M23: 15 | N23: 16 | O23: 18 | P23: 17 | Q23: 17 | R23: 19 | S23: 15 | T23: 16 | U23: 15 | V23: 15 | W23: 16 | X23: 16 | Y23: 16 | Z23: 16 | AA23: 16 | AB23: 15 | AD23: 15.89 | AE23: 143 | AG23: 6 | AH23: SUP | AI23: 1
A24: 17 | B24: PEREZ GOMEZ, Ashley Sara | D24: 15 | E24: 15 | F24: 16 | G24: 15 | H24: 14 | I24: 13 | J24: 13 | K24: 12 | L24: 14 | M24: 12 | N24: 14 | O24: 13 | P24: 14 | Q24: 12 | R24: 12 | S24: 13 | T24: 16 | U24: 11 | V24: 12 | W24: 16 | X24: 16 | Y24: 10 | Z24: 13 | AA24: 16 | AB24: 11 | AD24: 13.33 | AE24: 120 | AF24: 1 | AG24: 23 | AH24: INF | AI24: 4
A25: 18 | B25: RAMOS MELENDEZ, Aaron Pablo Wiliam | D25: 15 | E25: 16 | F25: 14 | G25: 16 | H25: 14 | I25: 14 | J25: 14 | K25: 14 | L25: 14 | M25: 15 | N25: 15 | O25: 15 | P25: 16 | Q25: 12 | R25: 17 | S25: 14 | T25: 16 | U25: 12 | V25: 14 | W25: 15 | X25: 15 | Y25: 11 | Z25: 13 | AA25: 16 | AB25: 13 | AD25: 14 | AE25: 126 | AG25: 18 | AH25: INF | AI25: 2
A26: 19 | B26: ROSALES ESPINOZA, Yamila Sayury | D26: 16 | E26: 16 | F26: 16 | G26: 18 | H26: 15 | I26: 15 | J26: 17 | K26: 15 | L26: 14 | M26: 15 | N26: 16 | O26: 18 | P26: 18 | Q26: 16 | R26: 19 | S26: 16 | T26: 17 | U26: 15 | V26: 15 | W26: 16 | X26: 16 | Y26: 18 | Z26: 16 | AA26: 16 | AB26: 16 | AD26: 16.33 | AE26: 147 | AG26: 4 | AH26: SUP
A27: 20 | B27: SANCHEZ ROSALES, Danna Gaela | D27: 15 | E27: 15 | F27: 13 | G27: 16 | H27: 14 | I27: 13 | J27: 13 | K27: 13 | L27: 15 | M27: 12 | N27: 14 | O27: 13 | P27: 15 | Q27: 11 | R27: 14 | S27: 14 | T27: 14 | U27: 14 | V27: 14 | W27: 17 | X27: 17 | Y27: 11 | Z27: 12 | AA27: 16 | AB27: 12 | AD27: 13.67 | AE27: 123 | AG27: 20 | AH27: INF | AI27: 1
A28: 21 | B28: USCAMAYTA CRISTOBAL, Cristobal Belinda | D28: 16 | E28: 16 | F28: 16 | G28: 17 | H28: 14 | I28: 17 | J28: 18 | K28: 16 | L28: 16 | M28: 18 | N28: 19 | O28: 18 | P28: 19 | Q28: 17 | R28: 19 | S28: 16 | T28: 18 | U28: 16 | V28: 13 | W28: 16 | X28: 16 | Y28: 10 | Z28: 17 | AA28: 16 | AB28: 17 | AD28: 15.89 | AE28: 143 | AF28: 1 | AG28: 6 | AH28: SUP
A29: 22 | B29: VALCARCEL DIAZ, Sihana Arabela | D29: 15 | E29: 15 | F29: 14 | G29: 14 | H29: 16 | I29: 14 | J29: 14 | K29: 11 | L29: 14 | M29: 14 | N29: 15 | O29: 14 | P29: 15 | Q29: 12 | R29: 16 | S29: 12 | T29: 14 | U29: 09 | V29: 13 | W29: 16 | X29: 16 | Y29: 14 | Z29: 14 | AA29: 16 | AB29: 12 | AD29: 14.11 | AE29: 127 | AG29: 17 | AH29: INF | AI29: 1
A30: 23 | B30: VARGAS VASQUEZ, Ayalen Danae | D30: 16 | E30: 16 | F30: 17 | G30: 17 | H30: 15 | I30: 18 | J30: 18 | K30: 17 | L30: 19 | M30: 19 | N30: 19 | O30: 18 | P30: 19 | Q30: 17 | R30: 19 | S30: 16 | T30: 18 | U30: 17 | V30: 14 | W30: 16 | X30: 16 | Y30: 19 | Z30: 18 | AA30: 16 | AB30: 17 | AD30: 17.11 | AE30: 154 | AG30: 2 | AH30: SUP | AI30: 2
A31: 24 | B31: VASQUEZ TAIÑA, Isaac Adriel | D31: 16 | E31: 16 | F31: 16 | G31: 16 | H31: 14 | I31: 16 | J31: 18 | K31: 17 | L31: 15 | M31: 16 | N31: 16 | O31: 16 | P31: 15 | Q31: 17 | R31: 15 | S31: 16 | T31: 17 | U31: 16 | V31: 15 | W31: 15 | X31: 15 | Y31: 12 | Z31: 14 | AA31: 16 | AB31: 13 | AD31: 14.89 | AE31: 134 | AG31: 13 | AH31: MED | AI31: 10
A32: 25 | B32: VEGA GUISASOLA, Lennyn | D32: 14 | E32: 14 | F32: 13 | G32: 15 | H32: 15 | I32: 14 | J32: 15 | K32: 11 | L32: 14 | M32: 14 | N32: 14 | O32: 14 | P32: 14 | Q32: 12 | R32: 17 | S32: 14 | T32: 15 | U32: 14 | V32: 13 | W32: 14 | X32: 14 | Y32: 11 | Z32: 13 | AA32: 16 | AB32: 11 | AD32: 13.44 | AE32: 121 | AG32: 22 | AH32: INF | AI32: 6
B34: Promedio del curso: | D34: 15.5 | E34: 15.4 | F34: 15.3 | G34: 16.4 | H34: 14.7 | I34: 14.8 | J34: 15.4 | K34: 14.2 | L34: 15 | M34: 14.4 | N34: 15.5 | O34: 15.6 | P34: 16 | Q34: 14.4 | R34: 16.2 | S34: 14.7 | T34: 16.1 | U34: 14.1 | V34: 13.9 | W34: 15.5 | X34: 15.5 | Y34: 14 | Z34: 14.5 | AA34: 16 | AB34: 13.8
B35: N° de alumnos Aprobados: | D35: 25 | E35: 25 | F35: 25 | G35: 25 | H35: 25 | I35: 25 | J35: 25 | K35: 24 | L35: 25 | M35: 25 | N35: 25 | O35: 25 | P35: 25 | Q35: 24 | R35: 25 | S35: 25 | T35: 25 | U35: 24 | V35: 25 | W35: 25 | X35: 25 | Y35: 23 | Z35: 25 | AA35: 25 | AB35: 25
B36: N° de alumnos Desaprobados: | K36: 1 | Q36: 1 | U36: 1 | Y36: 2
B37: % de alumnos Aprobados: | D37: 100 | E37: 100 | F37: 100 | G37: 100 | H37: 100 | I37: 100 | J37: 100 | K37: 96 | L37: 100 | M37: 100 | N37: 100 | O37: 100 | P37: 100 | Q37: 96 | R37: 100 | S37: 100 | T37: 100 | U37: 96 | V37: 100 | W37: 100 | X37: 100 | Y37: 92 | Z37: 100 | AA37: 100 | AB37: 100
B38: % de alumnos Desaprobados: | K38: 4 | Q38: 4 | U38: 4 | Y38: 8
B39: Nota Máxima: | D39: 17 | E39: 17 | F39: 19 | G39: 18 | H39: 16 | I39: 19 | J39: 18 | K39: 20 | L39: 19 | M39: 19 | N39: 19 | O39: 19 | P39: 19 | Q39: 19 | R39: 20 | S39: 17 | T39: 18 | U39: 17 | V39: 17 | W39: 17 | X39: 17 | Y39: 19 | Z39: 18 | AA39: 17 | AB39: 19
B40: Nota Mínima: | D40: 14 | E40: 14 | F40: 12 | G40: 14 | H40: 14 | I40: 12 | J40: 12 | K40: 10 | L40: 14 | M40: 12 | N40: 14 | O40: 13 | P40: 13 | Q40: 10 | R40: 12 | S40: 12 | T40: 13 | U40: 09 | V40: 11 | W40: 14 | X40: 14 | Y40: 10 | Z40: 12 | AA40: 15 | AB40: 11

Sheet 1AS 3B
A1: COLEGIOELROBLE | L1: Fecha: | N1: 09/12/2025
A2: CUBICOL Intranet | L2: Hora: | N2: 12:30:37
A3: CONSOLIDADO DE NOTAS - 2025
A5: Salón: | C5: 1ER AÑO A SECUNDARIA | D5: Periodo: | F5: 3er Bimestre | I5: Tutor: | K5: OLIVARES COELLO, Edilberto
A6: ASIGNATURAS | D6: COMUNICACIÓN | E6: Lenguaje | F6: Literatura | G6: Plan Lector | H6: Raz. Verbal | I6: MATEMÁTICAS | J6: Álgebra | K6: Aritmética | L6: Geometría | M6: Raz. Matemático | N6: Trigonometría | O6: CIENCIA Y TECNOLOGÍA | P6: Biología | Q6: Física | R6: Química | S6: CIENCIAS SOCIALES | T6: Geografía | U6: Historia del Perú | V6: Historia Universal | W6: EDUCACIÓN PARA EL TRABAJO | X6: Computación | Y6: ARTE Y CULTURA | Z6: DESARROLLO PERSONAL Y CIUDADANA CÍVICA | AA6: EDUCACIÓN FISICA | AB6: INGLES | AC6: CONDUCTA | AD6: PROMEDIO | AE6: PUNTAJE | AF6: N° DESAPROBADOS | AG6: ORDEN DE MÉRITO | AH6: TERCIO | AI6: Tardanza Injustificada | AJ6: Tardanza Justificada | AK6: Falta Injustificada | AL6: Falta Justificada
A7: N° | B7: APELLIDOS Y NOMBRES
A8: 1 | B8: ALBINO CONDORI, Andre Anderson | D8: 14 | E8: 13 | F8: 14 | G8: 16 | H8: 14 | I8: 14 | J8: 12 | K8: 13 | L8: 17 | M8: 12 | N8: 14 | O8: 14 | P8: 15 | Q8: 14 | R8: 13 | S8: 14 | T8: 12 | U8: 14 | V8: 15 | W8: 15 | X8: 15 | Y8: 15 | Z8: 14 | AA8: 17 | AB8: 13 | AD8: 14.44 | AE8: 130 | AG8: 14 | AH8: MED | AI8: 12
A9: 2 | B9: ALVARADO ACOSTA, Debora Abigail | D9: 16 | E9: 15 | F9: 15 | G9: 18 | H9: 15 | I9: 15 | J9: 15 | K9: 14 | L9: 16 | M9: 15 | N9: 14 | O9: 15 | P9: 15 | Q9: 15 | R9: 16 | S9: 16 | T9: 18 | U9: 15 | V9: 16 | W9: 17 | X9: 17 | Y9: 15 | Z9: 13 | AA9: 17 | AB9: 14 | AD9: 15.33 | AE9: 138 | AG9: 9 | AH9: MED | AI9: 4
A10: 3 | B10: BENITES ACOSTA, Cielo Guadalupe | D10: 13 | E10: 13 | F10: 11 | G10: 15 | H10: 13 | I10: 12 | J10: 11 | K10: 11 | L10: 14 | M10: 11 | N10: 13 | O10: 13 | P10: 12 | Q10: 13 | R10: 13 | S10: 12 | T10: 09 | U10: 13 | V10: 15 | W10: 16 | X10: 16 | Y10: 14 | Z10: 11 | AA10: 14 | AB10: 12 | AD10: 13 | AE10: 117 | AG10: 25 | AH10: INF
A11: 4 | B11: CABANILLAS HUAYLLAHUA | D11: 16 | E11: 14 | F11: 17 | G11: 19 | H11: 15 | I11: 14 | J11: 13 | K11: 15 | L11: 17 | M11: 12 | N11: 14 | O11: 16 | P11: 18 | Q11: 15 | R11: 16 | S11: 14 | T11: 14 | U11: 14 | V11: 15 | W11: 16 | X11: 16 | Y11: 16 | Z11: 14 | AA11: 15 | AB11: 14 | AD11: 15 | AE11: 135 | AG11: 12 | AH11: MED | AI11: 1
A12: 5 | B12: CENTENO TARAZONA, Camila Adriana | D12: 16 | E12: 15 | F12: 15 | G12: 19 | H12: 14 | I12: 15 | J12: 14 | K12: 16 | L12: 17 | M12: 14 | N12: 15 | O12: 17 | P12: 18 | Q12: 15 | R12: 18 | S12: 15 | T12: 14 | U12: 16 | V12: 16 | W12: 17 | X12: 17 | Y12: 16 | Z12: 16 | AA12: 15 | AB12: 15 | AD12: 15.78 | AE12: 142 | AG12: 6 | AH12: SUP
A13: 6 | B13: CHAHUARES HUAMANI, Lucero Andrea | D13: 15 | E13: 14 | F13: 14 | G13: 18 | H13: 15 | I13: 14 | J13: 15 | K13: 12 | L13: 17 | M13: 13 | N13: 15 | O13: 16 | P13: 17 | Q13: 17 | R13: 14 | S13: 15 | T13: 15 | U13: 15 | V13: 15 | W13: 17 | X13: 17 | Y13: 16 | Z13: 14 | AA13: 13 | AB13: 16 | AD13: 15.11 | AE13: 136 | AG13: 10 | AH13: MED
A14: 7 | B14: DURAND CRUZADO, Christian Gabriel | D14: 15 | E14: 15 | F14: 13 | G14: 16 | H14: 16 | I14: 12 | J14: 12 | K14: 11 | L14: 14 | M14: 12 | N14: 13 | O14: 13 | P14: 15 | Q14: 13 | R14: 11 | S14: 13 | T14: 12 | U14: 13 | V14: 15 | W14: 15 | X14: 15 | Y14: 14 | Z14: 12 | AA14: 15 | AB14: 13 | AD14: 13.56 | AE14: 122 | AG14: 23 | AH14: INF | AI14: 3
A15: 8 | B15: FIGUEROA PALOMINO, Yanely Nicol | D15: 15 | E15: 15 | F15: 15 | G15: 16 | H15: 15 | I15: 15 | J15: 15 | K15: 14 | L15: 16 | M15: 15 | N15: 14 | O15: 15 | P15: 12 | Q15: 16 | R15: 18 | S15: 15 | T15: 17 | U15: 14 | V15: 15 | W15: 17 | X15: 17 | Y15: 15 | Z15: 14 | AA15: 14 | AB15: 16 | AD15: 15.11 | AE15: 136 | AG15: 10 | AH15: MED | AI15: 3
A16: 9 | B16: FRANCISCO RAMIREZ, Lucero Kasumy | D16: 13 | E16: 12 | F16: 12 | G16: 14 | H16: 13 | I16: 13 | J16: 11 | K16: 13 | L16: 14 | M16: 11 | N16: 14 | O16: 14 | P16: 17 | Q16: 13 | R16: 12 | S16: 13 | T16: 13 | U16: 14 | V16: 13 | W16: 16 | X16: 16 | Y16: 16 | Z16: 11 | AA16: 15 | AB16: 12 | AD16: 13.67 | AE16: 123 | AG16: 20 | AH16: INF | AI16: 2
A17: 10 | B17: GUTIERREZ SANCHEZ, Joshua David | D17: 16 | E17: 17 | F17: 16 | G17: 17 | H17: 15 | I17: 17 | J17: 17 | K17: 18 | L17: 18 | M17: 15 | N17: 18 | O17: 17 | P17: 16 | Q17: 17 | R17: 19 | S17: 17 | T17: 18 | U17: 15 | V17: 18 | W17: 17 | X17: 17 | Y17: 16 | Z17: 15 | AA17: 14 | AB17: 17 | AD17: 16.22 | AE17: 146 | AG17: 4 | AH17: SUP | AI17: 5
A18: 11 | B18: JAIMES VILLADEZA, Mari Meredid | D18: 15 | E18: 15 | F18: 14 | G18: 16 | H18: 15 | I18: 14 | J18: 12 | K18: 14 | L18: 16 | M18: 12 | N18: 17 | O18: 14 | P18: 14 | Q18: 15 | R18: 14 | S18: 14 | T18: 14 | U18: 14 | V18: 14 | W18: 16 | X18: 16 | Y18: 15 | Z18: 15 | AA18: 14 | AB18: 12 | AD18: 14.33 | AE18: 129 | AG18: 15 | AH18: MED | AI18: 1
A19: 12 | B19: JAVES CASTRO, Yaretzy Valeria Anahid | D19: 15 | E19: 13 | F19: 16 | G19: 17 | H19: 15 | I19: 14 | J19: 13 | K19: 13 | L19: 16 | M19: 12 | N19: 14 | O19: 13 | P19: 13 | Q19: 14 | R19: 11 | S19: 14 | T19: 15 | U19: 14 | V19: 14 | W19: 17 | X19: 17 | Y19: 15 | Z19: 14 | AA19: 14 | AB19: 13 | AD19: 14.33 | AE19: 129 | AG19: 15 | AH19: MED | AI19: 5 | AK19: 1
A20: 13 | B20: MORI ANDRADE, Juan Diego | D20: 14 | E20: 14 | F20: 11 | G20: 15 | H20: 14 | I20: 12 | J20: 12 | K20: 10 | L20: 15 | M20: 11 | N20: 13 | O20: 13 | Q20: 13 | R20: 12 | S20: 13 | T20: 12 | U20: 13 | V20: 13 | W20: 15 | X20: 15 | Y20: 14 | Z20: 13 | AA20: 17 | AB20: 13 | AD20: 13.78 | AE20: 124 | AG20: 19 | AH20: INF | AK20: 3
A21: 14 | B21: NANFUÑAY LLUEN, Gerson David | D21: 17 | E21: 16 | F21: 17 | G21: 18 | H21: 16 | I21: 18 | J21: 18 | K21: 18 | L21: 19 | M21: 17 | N21: 18 | O21: 18 | P21: 17 | Q21: 18 | R21: 18 | S21: 18 | T21: 20 | U21: 16 | V21: 18 | W21: 17 | X21: 17 | Y21: 17 | Z21: 16 | AA21: 16 | AB21: 18 | AD21: 17.22 | AE21: 155 | AG21: 1 | AH21: SUP
A22: 15 | B22: NINAQUISPE AYALA, Dayron Yahir | D22: 15 | E22: 14 | F22: 14 | G22: 15 | H22: 15 | I22: 13 | J22: 13 | K22: 12 | L22: 16 | M22: 12 | N22: 13 | O22: 13 | P22: 13 | Q22: 13 | R22: 13 | S22: 12 | T22: 10 | U22: 10 | V22: 15 | W22: 16 | X22: 16 | Y22: 14 | Z22: 13 | AA22: 16 | AB22: 13 | AD22: 13.89 | AE22: 125 | AG22: 18 | AH22: INF
A23: 16 | B23: PASACHE HONORES, Martin Nicolas | D23: 15 | E23: 15 | F23: 14 | G23: 17 | H23: 15 | I23: 15 | J23: 14 | K23: 13 | L23: 17 | M23: 15 | N23: 16 | O23: 16 | P23: 16 | Q23: 17 | R23: 16 | S23: 16 | T23: 17 | U23: 15 | V23: 15 | W23: 16 | X23: 16 | Y23: 16 | Z23: 16 | AA23: 15 | AB23: 16 | AD23: 15.67 | AE23: 141 | AG23: 7 | AH23: SUP
A24: 17 | B24: PEREZ GOMEZ, Ashley Sara | D24: 15 | E24: 13 | F24: 15 | G24: 15 | H24: 15 | I24: 12 | J24: 11 | K24: 10 | L24: 14 | M24: 11 | N24: 14 | O24: 13 | P24: 17 | Q24: 10 | R24: 12 | S24: 12 | T24: 10 | U24: 14 | V24: 13 | W24: 16 | X24: 16 | Y24: 14 | Z24: 15 | AA24: 14 | AB24: 11 | AD24: 13.56 | AE24: 122 | AG24: 23 | AH24: INF | AI24: 2 | AK24: 3
A25: 18 | B25: RAMOS MELENDEZ, Aaron Pablo Wiliam | D25: 13 | E25: 13 | F25: 11 | G25: 13 | H25: 14 | I25: 13 | J25: 11 | K25: 13 | L25: 16 | M25: 12 | N25: 14 | O25: 13 | P25: 13 | Q25: 14 | R25: 12 | S25: 14 | T25: 16 | U25: 13 | V25: 14 | W25: 15 | X25: 15 | Y25: 13 | Z25: 14 | AA25: 15 | AB25: 13 | AD25: 13.67 | AE25: 123 | AG25: 20 | AH25: INF | AK25: 2
A26: 19 | B26: ROSALES ESPINOZA, Yamila Sayury | D26: 16 | E26: 16 | F26: 15 | G26: 18 | H26: 15 | I26: 16 | J26: 15 | K26: 18 | L26: 18 | M26: 16 | N26: 15 | O26: 16 | P26: 17 | Q26: 16 | R26: 16 | S26: 17 | T26: 18 | U26: 16 | V26: 17 | W26: 16 | X26: 16 | Y26: 18 | Z26: 15 | AA26: 16 | AB26: 15 | AD26: 16.11 | AE26: 145 | AG26: 5 | AH26: SUP
A27: 20 | B27: SANCHEZ ROSALES, Danna Gaela | D27: 13 | E27: 13 | F27: 11 | G27: 16 | H27: 12 | I27: 13 | J27: 11 | K27: 12 | L27: 16 | M27: 11 | N27: 14 | O27: 13 | P27: 14 | Q27: 13 | R27: 12 | S27: 14 | T27: 10 | U27: 16 | V27: 15 | W27: 16 | X27: 16 | Y27: 17 | Z27: 13 | AA27: 15 | AB27: 13 | AD27: 14.11 | AE27: 127 | AG27: 17 | AH27: INF
A28: 21 | B28: USCAMAYTA CRISTOBAL, Cristobal Belinda | D28: 16 | E28: 15 | F28: 16 | G28: 19 | H28: 14 | I28: 17 | J28: 17 | K28: 17 | L28: 18 | M28: 16 | N28: 17 | O28: 17 | P28: 16 | Q28: 17 | R28: 17 | S28: 17 | T28: 20 | U28: 16 | V28: 16 | W28: 17 | X28: 17 | Y28: 17 | Z28: 16 | AA28: 16 | AB28: 17 | AD28: 16.67 | AE28: 150 | AG28: 3 | AH28: SUP
A29: 22 | B29: VALCARCEL DIAZ, Sihana Arabela | D29: 15 | E29: 15 | F29: 12 | G29: 16 | H29: 15 | I29: 13 | J29: 13 | K29: 12 | L29: 15 | M29: 12 | N29: 14 | O29: 12 | P29: 11 | Q29: 13 | R29: 13 | S29: 15 | T29: 18 | U29: 13 | V29: 15 | W29: 16 | X29: 16 | Y29: 17 | Z29: 15 | AA29: 15 | AB29: 15 | AD29: 14.78 | AE29: 133 | AG29: 13 | AH29: MED | AI29: 1
A30: 23 | B30: VARGAS VASQUEZ, Ayalen Danae | D30: 16 | E30: 15 | F30: 15 | G30: 18 | H30: 15 | I30: 19 | J30: 19 | K30: 19 | L30: 19 | M30: 18 | N30: 18 | O30: 18 | P30: 17 | Q30: 19 | R30: 19 | S30: 16 | T30: 16 | U30: 15 | V30: 16 | W30: 17 | X30: 17 | Y30: 19 | Z30: 17 | AA30: 14 | AB30: 15 | AD30: 16.78 | AE30: 151 | AG30: 2 | AH30: SUP | AI30: 1
A31: 24 | B31: VASQUEZ TAIÑA, Isaac Adriel | D31: 15 | E31: 15 | F31: 13 | G31: 14 | H31: 17 | I31: 16 | J31: 16 | K31: 15 | L31: 17 | M31: 15 | N31: 16 | O31: 15 | P31: 13 | Q31: 17 | R31: 15 | S31: 14 | T31: 13 | U31: 12 | V31: 16 | W31: 17 | X31: 17 | Y31: 14 | Z31: 17 | AA31: 15 | AB31: 17 | AD31: 15.56 | AE31: 140 | AG31: 8 | AH31: SUP | AI31: 4 | AK31: 3
A32: 25 | B32: VEGA GUISASOLA, Lennyn | D32: 14 | E32: 14 | F32: 13 | G32: 14 | H32: 15 | I32: 13 | J32: 12 | K32: 11 | L32: 15 | M32: 12 | N32: 15 | O32: 13 | P32: 13 | Q32: 13 | R32: 14 | S32: 13 | T32: 16 | U32: 10 | V32: 12 | W32: 15 | X32: 15 | Y32: 13 | Z32: 15 | AA32: 16 | AB32: 11 | AD32: 13.67 | AE32: 123 | AG32: 20 | AH32: INF | AI32: 5 | AK32: 5
B34: Promedio del curso: | D34: 14.9 | E34: 14.4 | F34: 14 | G34: 16.4 | H34: 14.7 | I34: 14.4 | J34: 13.7 | K34: 13.8 | L34: 16.3 | M34: 13.3 | N34: 14.9 | O34: 14.7 | P34: 15 | Q34: 14.8 | R34: 14.6 | S34: 14.5 | T34: 14.7 | U34: 14 | V34: 15 | W34: 16.2 | X34: 16.2 | Y34: 15.4 | Z34: 14.3 | AA34: 15.1 | AB34: 14.2
B35: N° de alumnos Aprobados: | D35: 25 | E35: 25 | F35: 25 | G35: 25 | H35: 25 | I35: 25 | J35: 25 | K35: 23 | L35: 25 | M35: 25 | N35: 25 | O35: 25 | P35: 24 | Q35: 24 | R35: 25 | S35: 25 | T35: 21 | U35: 23 | V35: 25 | W35: 25 | X35: 25 | Y35: 25 | Z35: 25 | AA35: 25 | AB35: 25
B36: N° de alumnos Desaprobados: | K36: 2 | Q36: 1 | T36: 4 | U36: 2
B37: % de alumnos Aprobados: | D37: 100 | E37: 100 | F37: 100 | G37: 100 | H37: 100 | I37: 100 | J37: 100 | K37: 92 | L37: 100 | M37: 100 | N37: 100 | O37: 100 | P37: 100 | Q37: 96 | R37: 100 | S37: 100 | T37: 84 | U37: 92 | V37: 100 | W37: 100 | X37: 100 | Y37: 100 | Z37: 100 | AA37: 100 | AB37: 100
B38: % de alumnos Desaprobados: | K38: 8 | Q38: 4 | T38: 16 | U38: 8
B39: Nota Máxima: | D39: 17 | E39: 17 | F39: 17 | G39: 19 | H39: 17 | I39: 19 | J39: 19 | K39: 19 | L39: 19 | M39: 18 | N39: 18 | O39: 18 | P39: 18 | Q39: 19 | R39: 19 | S39: 18 | T39: 20 | U39: 16 | V39: 18 | W39: 17 | X39: 17 | Y39: 19 | Z39: 17 | AA39: 17 | AB39: 18
B40: Nota Mínima: | D40: 13 | E40: 12 | F40: 11 | G40: 13 | H40: 12 | I40: 12 | J40: 11 | K40: 10 | L40: 14 | M40: 11 | N40: 13 | O40: 12 | P40: 11 | Q40: 10 | R40: 11 | S40: 12 | T40: 09 | U40: 10 | V40: 12 | W40: 15 | X40: 15 | Y40: 13 | Z40: 11 | AA40: 13 | AB40: 11

Sheet 1AS 4B
A1: COLEGIOELROBLE | L1: Fecha: | N1: 09/12/2025
A2: CUBICOL Intranet | L2: Hora: | N2: 12:30:57
A3: CONSOLIDADO DE NOTAS - 2025
A5: Salón: | C5: 1ER AÑO A SECUNDARIA | D5: Periodo: | F5: 4to Bimestre | I5: Tutor: | K5: OLIVARES COELLO, Edilberto
A6: ASIGNATURAS | D6: COMUNICACIÓN | E6: Lenguaje | F6: Literatura | G6: Plan Lector | H6: Raz. Verbal | I6: MATEMÁTICAS | J6: Álgebra | K6: Aritmética | L6: Geometría | M6: Raz. Matemático | N6: Trigonometría | O6: CIENCIA Y TECNOLOGÍA | P6: Biología | Q6: Física | R6: Química | S6: CIENCIAS SOCIALES | T6: Geografía | U6: Historia del Perú | V6: Historia Universal | W6: EDUCACIÓN PARA EL TRABAJO | X6: Computación | Y6: ARTE Y CULTURA | Z6: DESARROLLO PERSONAL Y CIUDADANA CÍVICA | AA6: EDUCACIÓN FISICA | AB6: INGLES | AC6: CONDUCTA | AD6: PROMEDIO | AE6: PUNTAJE | AF6: N° DESAPROBADOS | AG6: ORDEN DE MÉRITO | AH6: TERCIO | AI6: Tardanza Injustificada | AJ6: Tardanza Justificada | AK6: Falta Injustificada | AL6: Falta Justificada
A7: N° | B7: APELLIDOS Y NOMBRES
A8: 1 | B8: ALBINO CONDORI, Andre Anderson | D8: 13 | E8: 13 | F8: 13 | G8: 12 | H8: 14 | I8: 15 | J8: 14 | K8: 14 | L8: 16 | M8: 13 | N8: 17 | O8: 15 | P8: 15 | Q8: 14 | R8: 17 | S8: 15 | T8: 17 | U8: 15 | V8: 14 | W8: 16 | X8: 16 | Y8: 15 | Z8: 15 | AA8: 15 | AB8: 12 | AD8: 14.56 | AE8: 131 | AG8: 17 | AH8: INF | AI8: 7
A9: 2 | B9: ALVARADO ACOSTA, Debora Abigail | D9: 17 | E9: 16 | F9: 17 | G9: 18 | H9: 16 | I9: 16 | J9: 15 | K9: 16 | L9: 16 | M9: 17 | N9: 16 | O9: 16 | P9: 14 | Q9: 16 | R9: 17 | S9: 16 | T9: 18 | U9: 15 | V9: 15 | W9: 18 | X9: 18 | Y9: 14 | Z9: 15 | AA9: 15 | AB9: 15 | AD9: 15.78 | AE9: 142 | AG9: 7 | AH9: SUP | AI9: 9
A10: 3 | B10: BENITES ACOSTA, Cielo Guadalupe | D10: 14 | E10: 15 | F10: 13 | G10: 14 | H10: 15 | I10: 14 | J10: 12 | K10: 13 | L10: 15 | M10: 13 | N10: 16 | O10: 14 | P10: 12 | Q10: 14 | R10: 17 | S10: 13 | T10: 15 | U10: 12 | V10: 12 | W10: 17 | X10: 17 | Y10: 13 | Z10: 12 | AA10: 15 | AB10: 13 | AD10: 13.89 | AE10: 125 | AG10: 24 | AH10: INF | AI10: 4
A11: 4 | B11: CABANILLAS HUAYLLAHUA | D11: 17 | E11: 17 | F11: 17 | G11: 17 | H11: 16 | I11: 16 | J11: 14 | K11: 17 | L11: 16 | M11: 16 | N11: 17 | O11: 17 | P11: 17 | Q11: 16 | R11: 19 | S11: 15 | T11: 18 | U11: 14 | V11: 14 | W11: 18 | X11: 18 | Y11: 14 | Z11: 13 | AA11: 15 | AB11: 15 | AD11: 15.56 | AE11: 140 | AG11: 10 | AH11: MED | AI11: 2
A12: 5 | B12: CENTENO TARAZONA, Camila Adriana | D12: 17 | E12: 16 | F12: 16 | G12: 17 | H12: 17 | I12: 17 | J12: 15 | K12: 18 | L12: 17 | M12: 16 | N12: 17 | O12: 16 | P12: 14 | Q12: 16 | R12: 19 | S12: 16 | T12: 18 | U12: 14 | V12: 15 | W12: 17 | X12: 17 | Y12: 16 | Z12: 17 | AA12: 16 | AB12: 15 | AD12: 16.33 | AE12: 147 | AG12: 4 | AH12: SUP | AI12: 3
A13: 6 | B13: CHAHUARES HUAMANI, Lucero Andrea | D13: 15 | E13: 14 | F13: 15 | G13: 16 | H13: 15 | I13: 16 | J13: 16 | K13: 17 | L13: 16 | M13: 16 | N13: 17 | O13: 16 | P13: 17 | Q13: 15 | R13: 17 | S13: 15 | T13: 18 | U13: 15 | V13: 12 | W13: 17 | X13: 17 | Y13: 16 | Z13: 16 | AA13: 16 | AB13: 15 | AD13: 15.78 | AE13: 142 | AG13: 7 | AH13: SUP
A14: 7 | B14: DURAND CRUZADO, Christian Gabriel | D14: 14 | E14: 15 | F14: 13 | G14: 13 | H14: 14 | I14: 15 | J14: 12 | K14: 16 | L14: 15 | M14: 14 | N14: 16 | O14: 15 | P14: 13 | Q14: 16 | R14: 17 | S14: 16 | T14: 17 | U14: 14 | V14: 16 | W14: 15 | X14: 15 | Y14: 14 | Z14: 13 | AA14: 16 | AB14: 12 | AD14: 14.44 | AE14: 130 | AG14: 19 | AH14: INF | AI14: 1
A15: 8 | B15: FIGUEROA PALOMINO, Yanely Nicol | D15: 16 | E15: 15 | F15: 17 | G15: 16 | H15: 15 | I15: 16 | J15: 16 | K15: 16 | L15: 16 | M15: 17 | N15: 16 | O15: 15 | P15: 13 | Q15: 16 | R15: 17 | S15: 17 | T15: 18 | U15: 15 | V15: 17 | W15: 16 | X15: 16 | Y15: 15 | Z15: 16 | AA15: 15 | AB15: 16 | AD15: 15.78 | AE15: 142 | AG15: 7 | AH15: SUP | AI15: 8
A16: 9 | B16: FRANCISCO RAMIREZ, Lucero Kasumy | D16: 13 | E16: 13 | F16: 15 | G16: 12 | H16: 13 | I16: 15 | J16: 12 | K16: 16 | L16: 16 | M16: 13 | N16: 16 | O16: 16 | P16: 15 | Q16: 17 | R16: 17 | S16: 15 | T16: 17 | U16: 14 | V16: 13 | W16: 12 | X16: 12 | Y16: 15 | Z16: 14 | AA16: 16 | AB16: 13 | AD16: 14.33 | AE16: 129 | AG16: 20 | AH16: INF | AI16: 1
A17: 10 | B17: GUTIERREZ SANCHEZ, Joshua David | D17: 15 | E17: 16 | F17: 16 | G17: 15 | H17: 14 | I17: 17 | J17: 17 | K17: 17 | L17: 17 | M17: 18 | N17: 18 | O17: 17 | P17: 15 | Q17: 18 | R17: 19 | S17: 17 | T17: 18 | U17: 16 | V17: 16 | W17: 17 | X17: 17 | Y17: 16 | Z17: 17 | AA17: 16 | AB17: 17 | AD17: 16.56 | AE17: 149 | AG17: 3 | AH17: SUP | AI17: 1
A18: 11 | B18: JAIMES VILLADEZA, Mari Meredid | D18: 16 | E18: 16 | F18: 16 | G18: 15 | H18: 16 | I18: 16 | J18: 13 | K18: 16 | L18: 17 | M18: 15 | N18: 17 | O18: 16 | P18: 13 | Q18: 15 | R18: 19 | S18: 14 | T18: 17 | U18: 13 | V18: 13 | W18: 16 | X18: 16 | Y18: 16 | Z18: 17 | AA18: 17 | AB18: 12 | AD18: 15.56 | AE18: 140 | AG18: 10 | AH18: MED | AI18: 7
A19: 12 | B19: JAVES CASTRO, Yaretzy Valeria Anahid | D19: 16 | E19: 16 | F19: 17 | G19: 15 | H19: 15 | I19: 15 | J19: 14 | K19: 16 | L19: 16 | M19: 15 | N19: 16 | O19: 16 | P19: 14 | Q19: 15 | R19: 18 | S19: 16 | T19: 16 | U19: 16 | V19: 15 | W19: 15 | X19: 15 | Y19: 14 | Z19: 13 | AA19: 17 | AB19: 13 | AD19: 15 | AE19: 135 | AG19: 15 | AH19: MED | AI19: 6
A20: 13 | B20: MORI ANDRADE, Juan Diego | D20: 14 | E20: 16 | F20: 14 | G20: 13 | H20: 14 | I20: 14 | J20: 12 | K20: 15 | L20: 15 | M20: 14 | N20: 16 | O20: 16 | P20: 15 | Q20: 14 | R20: 18 | S20: 15 | T20: 17 | U20: 16 | V20: 13 | W20: 16 | X20: 16 | Y20: 14 | Z20: 13 | AA20: 17 | AB20: 13 | AD20: 14.67 | AE20: 132 | AG20: 16 | AH20: MED | AI20: 4
A21: 14 | B21: NANFUÑAY LLUEN, Gerson David | D21: 17 | E21: 16 | F21: 18 | G21: 19 | H21: 16 | I21: 19 | J21: 19 | K21: 19 | L21: 19 | M21: 18 | N21: 19 | O21: 19 | P21: 17 | Q21: 19 | R21: 20 | S21: 17 | T21: 19 | U21: 17 | V21: 16 | W21: 18 | X21: 18 | Y21: 18 | Z21: 18 | AA21: 16 | AB21: 19 | AD21: 17.89 | AE21: 161 | AG21: 1 | AH21: SUP
A22: 15 | B22: NINAQUISPE AYALA, Dayron Yahir | D22: 15 | E22: 16 | F22: 15 | G22: 13 | H22: 16 | I22: 15 | J22: 14 | K22: 15 | L22: 15 | M22: 15 | N22: 16 | O22: 17 | P22: 13 | Q22: 18 | R22: 19 | S22: 15 | T22: 17 | U22: 14 | V22: 13 | W22: 17 | X22: 17 | Y22: 15 | Z22: 13 | AA22: 16 | AB22: 13 | AD22: 15.11 | AE22: 136 | AG22: 14 | AH22: MED | AI22: 1
A23: 16 | B23: PASACHE HONORES, Martin Nicolas | D23: 17 | E23: 17 | F23: 17 | G23: 16 | H23: 16 | I23: 16 | J23: 15 | K23: 15 | L23: 17 | M23: 16 | N23: 17 | O23: 17 | P23: 17 | Q23: 16 | R23: 19 | S23: 16 | T23: 18 | U23: 15 | V23: 15 | W23: 15 | X23: 15 | Y23: 16 | Z23: 15 | AA23: 16 | AB23: 17 | AD23: 16.11 | AE23: 145 | AG23: 5 | AH23: SUP
A24: 17 | B24: PEREZ GOMEZ, Ashley Sara | D24: 16 | E24: 16 | F24: 17 | G24: 14 | H24: 15 | I24: 14 | J24: 12 | K24: 13 | L24: 15 | M24: 13 | N24: 16 | O24: 15 | P24: 14 | Q24: 14 | R24: 16 | S24: 13 | T24: 17 | U24: 10 | V24: 13 | W24: 15 | X24: 15 | Y24: 14 | Z24: 14 | AA24: 16 | AB24: 11 | AD24: 14.22 | AE24: 128 | AG24: 21 | AH24: INF | AI24: 4
A25: 18 | B25: RAMOS MELENDEZ, Aaron Pablo Wiliam | D25: 15 | E25: 15 | F25: 14 | G25: 15 | H25: 16 | I25: 14 | J25: 12 | K25: 14 | L25: 15 | M25: 13 | N25: 16 | O25: 16 | P25: 14 | Q25: 14 | R25: 19 | S25: 13 | T25: 17 | U25: 10 | V25: 12 | W25: 15 | X25: 15 | Y25: 12 | Z25: 11 | AA25: 15 | AB25: 12 | AD25: 13.67 | AE25: 123 | AG25: 25 | AH25: INF | AI25: 1
A26: 19 | B26: ROSALES ESPINOZA, Yamila Sayury | D26: 16 | E26: 16 | F26: 16 | G26: 17 | H26: 16 | I26: 17 | J26: 17 | K26: 17 | L26: 17 | M26: 18 | N26: 17 | O26: 17 | P26: 16 | Q26: 17 | R26: 19 | S26: 16 | T26: 18 | U26: 16 | V26: 15 | W26: 16 | X26: 16 | Y26: 16 | Z26: 13 | AA26: 14 | AB26: 15 | AD26: 15.56 | AE26: 140 | AG26: 10 | AH26: MED
A27: 20 | B27: SANCHEZ ROSALES, Danna Gaela | D27: 15 | E27: 16 | F27: 13 | G27: 14 | H27: 17 | I27: 15 | J27: 12 | K27: 15 | L27: 17 | M27: 13 | N27: 16 | O27: 14 | P27: 12 | Q27: 14 | R27: 17 | S27: 15 | T27: 18 | U27: 13 | V27: 13 | W27: 15 | X27: 15 | Y27: 14 | Z27: 14 | AA27: 15 | AB27: 11 | AD27: 14.22 | AE27: 128 | AG27: 21 | AH27: INF | AI27: 1
A28: 21 | B28: USCAMAYTA CRISTOBAL, Cristobal Belinda | D28: 17 | E28: 16 | F28: 16 | G28: 19 | H28: 17 | I28: 18 | J28: 18 | K28: 19 | L28: 18 | M28: 18 | N28: 18 | O28: 17 | P28: 16 | Q28: 16 | R28: 20 | S28: 14 | T28: 19 | U28: 10 | V28: 13 | W28: 17 | X28: 17 | Y28: 14 | Z28: 13 | AA28: 16 | AB28: 17 | AD28: 15.89 | AE28: 143 | AG28: 6 | AH28: SUP
A29: 22 | B29: VALCARCEL DIAZ, Sihana Arabela | D29: 15 | E29: 16 | F29: 14 | G29: 13 | H29: 15 | I29: 14 | J29: 13 | K29: 12 | L29: 16 | M29: 15 | N29: 16 | O29: 14 | P29: 13 | Q29: 13 | R29: 17 | S29: 14 | T29: 17 | U29: 11 | V29: 14 | W29: 18 | X29: 18 | Y29: 13 | Z29: 14 | AA29: 16 | AB29: 13 | AD29: 14.56 | AE29: 131 | AG29: 17 | AH29: INF | AI29: 1
A30: 23 | B30: VARGAS VASQUEZ, Ayalen Danae | D30: 17 | E30: 17 | F30: 17 | G30: 18 | H30: 17 | I30: 19 | J30: 20 | K30: 19 | L30: 19 | M30: 20 | N30: 19 | O30: 18 | P30: 16 | Q30: 17 | R30: 20 | S30: 17 | T30: 19 | U30: 16 | V30: 16 | W30: 17 | X30: 17 | Y30: 18 | Z30: 18 | AA30: 15 | AB30: 14 | AD30: 17 | AE30: 153 | AG30: 2 | AH30: SUP | AI30: 12
A31: 24 | B31: VASQUEZ TAIÑA, Isaac Adriel | D31: 15 | E31: 17 | F31: 14 | G31: 13 | H31: 15 | I31: 16 | J31: 17 | K31: 14 | L31: 17 | M31: 17 | N31: 17 | O31: 17 | P31: 15 | Q31: 16 | R31: 19 | S31: 16 | T31: 17 | U31: 15 | V31: 15 | W31: 15 | X31: 15 | Y31: 14 | Z31: 14 | AA31: 16 | AB31: 16 | AD31: 15.44 | AE31: 139 | AG31: 13 | AH31: MED | AI31: 8
A32: 25 | B32: VEGA GUISASOLA, Lennyn | D32: 15 | E32: 16 | F32: 15 | G32: 14 | H32: 15 | I32: 15 | J32: 13 | K32: 15 | L32: 15 | M32: 16 | N32: 16 | O32: 15 | P32: 13 | Q32: 14 | R32: 19 | S32: 12 | T32: 16 | U32: 10 | V32: 10 | W32: 16 | X32: 16 | Y32: 11 | Z32: 13 | AA32: 16 | AB32: 13 | AD32: 14 | AE32: 126 | AG32: 23 | AH32: INF | AI32: 6
B34: Promedio del curso: | D34: 15.5 | E34: 15.7 | F34: 15.4 | G34: 15.1 | H34: 15.4 | I34: 15.8 | J34: 14.6 | K34: 15.8 | L34: 16.3 | M34: 15.6 | N34: 16.7 | O34: 16 | P34: 14.5 | Q34: 15.6 | R34: 18.2 | S34: 15.1 | T34: 17.4 | U34: 13.8 | V34: 14 | W34: 16.2 | X34: 16.2 | Y34: 14.7 | Z34: 14.4 | AA34: 15.7 | AB34: 14.1
B35: N° de alumnos Aprobados: | D35: 25 | E35: 25 | F35: 25 | G35: 25 | H35: 25 | I35: 25 | J35: 25 | K35: 25 | L35: 25 | M35: 25 | N35: 25 | O35: 25 | P35: 25 | Q35: 25 | R35: 25 | S35: 25 | T35: 25 | U35: 21 | V35: 24 | W35: 25 | X35: 25 | Y35: 25 | Z35: 25 | AA35: 25 | AB35: 25
B36: N° de alumnos Desaprobados: | U36: 4 | V36: 1
B37: % de alumnos Aprobados: | D37: 100 | E37: 100 | F37: 100 | G37: 100 | H37: 100 | I37: 100 | J37: 100 | K37: 100 | L37: 100 | M37: 100 | N37: 100 | O37: 100 | P37: 100 | Q37: 100 | R37: 100 | S37: 100 | T37: 100 | U37: 84 | V37: 96 | W37: 100 | X37: 100 | Y37: 100 | Z37: 100 | AA37: 100 | AB37: 100
B38: % de alumnos Desaprobados: | U38: 16 | V38: 4
B39: Nota Máxima: | D39: 17 | E39: 17 | F39: 18 | G39: 19 | H39: 17 | I39: 19 | J39: 20 | K39: 19 | L39: 19 | M39: 20 | N39: 19 | O39: 19 | P39: 17 | Q39: 19 | R39: 20 | S39: 17 | T39: 19 | U39: 17 | V39: 17 | W39: 18 | X39: 18 | Y39: 18 | Z39: 18 | AA39: 17 | AB39: 19
B40: Nota Mínima: | D40: 13 | E40: 13 | F40: 13 | G40: 12 | H40: 13 | I40: 14 | J40: 12 | K40: 12 | L40: 15 | M40: 13 | N40: 16 | O40: 14 | P40: 12 | Q40: 13 | R40: 16 | S40: 12 | T40: 15 | U40: 10 | V40: 10 | W40: 12 | X40: 12 | Y40: 11 | Z40: 11 | AA40: 14 | AB40: 11

Sheet PRIMERO
A1: COLEGIOELROBLE | L1: Fecha: | N1: 09/12/2025
A2: CUBICOL Intranet | L2: Hora: | N2: 12:29:56
A3: CONSOLIDADO DE NOTAS - 2025
A5: Salón: | C5: 1ER AÑO A SECUNDARIA | D5: Periodo: | F5: 1er Bimestre | I5: Tutor: | K5: OLIVARES COELLO, Edilberto
A6: ASIGNATURAS | D6: COMUNICACIÓN | E6: Lenguaje | F6: Literatura | G6: Plan Lector | H6: Raz. Verbal | I6: MATEMÁTICAS | J6: Álgebra | K6: Aritmética | L6: Geometría | M6: Raz. Matemático | N6: Trigonometría | O6: CIENCIA Y TECNOLOGÍA | P6: Biología | Q6: Física | R6: Química | S6: CIENCIAS SOCIALES | T6: Geografía | U6: Historia del Perú | V6: Historia Universal | W6: EDUCACIÓN PARA EL TRABAJO | X6: Computación | Y6: ARTE Y CULTURA | Z6: DESARROLLO PERSONAL Y CIUDADANA CÍVICA | AA6: EDUCACIÓN FISICA | AB6: INGLES | AC6: CONDUCTA | AD6: PROMEDIO | AE6: PUNTAJE | AF6: N° DESAPROBADOS | AG6: ORDEN DE MÉRITO | AH6: TERCIO | AI6: Tardanza Injustificada | AJ6: Tardanza Justificada | AK6: Falta Injustificada | AL6: Falta Justificada
A7: N° | B7: APELLIDOS Y NOMBRES
A8: 1 | B8: ALBINO CONDORI, Andre Anderson | D8: =IF('1AS 1B'!D8="","", IF(ROUND('1AS 1B'!D8,0)<=10,"C", IF(ROUND('1AS 1B'!D8,0)<=13,"B", IF(ROUND('1AS 1B'!D8,0)<=17,"A", IF(ROUND('1AS 1B'!D8,0)<=20,"AD",""))))) -> A | E8: =IF('1AS 1B'!E8="","", IF(ROUND('1AS 1B'!E8,0)<=10,"C", IF(ROUND('1AS 1B'!E8,0)<=13,"B", IF(ROUND('1AS 1B'!E8,0)<=17,"A", IF(ROUND('1AS 1B'!E8,0)<=20,"AD",""))))) -> A | F8: =IF('1AS 1B'!F8="","", IF(ROUND('1AS 1B'!F8,0)<=10,"C", IF(ROUND('1AS 1B'!F8,0)<=13,"B", IF(ROUND('1AS 1B'!F8,0)<=17,"A", IF(ROUND('1AS 1B'!F8,0)<=20,"AD",""))))) -> A | G8: =IF('1AS 1B'!G8="","", IF(ROUND('1AS 1B'!G8,0)<=10,"C", IF(ROUND('1AS 1B'!G8,0)<=13,"B", IF(ROUND('1AS 1B'!G8,0)<=17,"A", IF(ROUND('1AS 1B'!G8,0)<=20,"AD",""))))) -> AD | H8: =IF('1AS 1B'!H8="","", IF(ROUND('1AS 1B'!H8,0)<=10,"C", IF(ROUND('1AS 1B'!H8,0)<=13,"B", IF(ROUND('1AS 1B'!H8,0)<=17,"A", IF(ROUND('1AS 1B'!H8,0)<=20,"AD",""))))) -> A | I8: =IF('1AS 1B'!I8="","", IF(ROUND('1AS 1B'!I8,0)<=10,"C", IF(ROUND('1AS 1B'!I8,0)<=13,"B", IF(ROUND('1AS 1B'!I8,0)<=17,"A", IF(ROUND('1AS 1B'!I8,0)<=20,"AD",""))))) -> A | J8: =IF('1AS 1B'!J8="","", IF(ROUND('1AS 1B'!J8,0)<=10,"C", IF(ROUND('1AS 1B'!J8,0)<=13,"B", IF(ROUND('1AS 1B'!J8,0)<=17,"A", IF(ROUND('1AS 1B'!J8,0)<=20,"AD",""))))) -> B | K8: =IF('1AS 1B'!K8="","", IF(ROUND('1AS 1B'!K8,0)<=10,"C", IF(ROUND('1AS 1B'!K8,0)<=13,"B", IF(ROUND('1AS 1B'!K8,0)<=17,"A", IF(ROUND('1AS 1B'!K8,0)<=20,"AD",""))))) -> A | ... AB8: =IF('1AS 1B'!AB8="","", IF(ROUND('1AS 1B'!AB8,0)<=10,"C", IF(ROUND('1AS 1B'!AB8,0)<=13,"B", IF(ROUND('1AS 1B'!AB8,0)<=17,"A", IF(ROUND('1AS 1B'!AB8,0)<=20,"AD",""))))) -> A | AD8: 15.44 | AE8: 139 | AG8: 13 | AH8: MED | AI8: 5 | AM8: =AE8+'1AS 2B'!AE8+'1AS 3B'!AE8+'1AS 4B'!AE8 -> 531 | AN8: =RANK(AM8,$AM$8:$AM$32, ) -> 15
A9: 2 | B9: ALVARADO ACOSTA, Debora Abigail | D9: =IF('1AS 1B'!D9="","", IF(ROUND('1AS 1B'!D9,0)<=10,"C", IF(ROUND('1AS 1B'!D9,0)<=13,"B", IF(ROUND('1AS 1B'!D9,0)<=17,"A", IF(ROUND('1AS 1B'!D9,0)<=20,"AD",""))))) -> A | E9: =IF('1AS 1B'!E9="","", IF(ROUND('1AS 1B'!E9,0)<=10,"C", IF(ROUND('1AS 1B'!E9,0)<=13,"B", IF(ROUND('1AS 1B'!E9,0)<=17,"A", IF(ROUND('1AS 1B'!E9,0)<=20,"AD",""))))) -> A | F9: =IF('1AS 1B'!F9="","", IF(ROUND('1AS 1B'!F9,0)<=10,"C", IF(ROUND('1AS 1B'!F9,0)<=13,"B", IF(ROUND('1AS 1B'!F9,0)<=17,"A", IF(ROUND('1AS 1B'!F9,0)<=20,"AD",""))))) -> AD | G9: =IF('1AS 1B'!G9="","", IF(ROUND('1AS 1B'!G9,0)<=10,"C", IF(ROUND('1AS 1B'!G9,0)<=13,"B", IF(ROUND('1AS 1B'!G9,0)<=17,"A", IF(ROUND('1AS 1B'!G9,0)<=20,"AD",""))))) -> A | H9: =IF('1AS 1B'!H9="","", IF(ROUND('1AS 1B'!H9,0)<=10,"C", IF(ROUND('1AS 1B'!H9,0)<=13,"B", IF(ROUND('1AS 1B'!H9,0)<=17,"A", IF(ROUND('1AS 1B'!H9,0)<=20,"AD",""))))) -> A | I9: =IF('1AS 1B'!I9="","", IF(ROUND('1AS 1B'!I9,0)<=10,"C", IF(ROUND('1AS 1B'!I9,0)<=13,"B", IF(ROUND('1AS 1B'!I9,0)<=17,"A", IF(ROUND('1AS 1B'!I9,0)<=20,"AD",""))))) -> A | J9: =IF('1AS 1B'!J9="","", IF(ROUND('1AS 1B'!J9,0)<=10,"C", IF(ROUND('1AS 1B'!J9,0)<=13,"B", IF(ROUND('1AS 1B'!J9,0)<=17,"A", IF(ROUND('1AS 1B'!J9,0)<=20,"AD",""))))) -> A | K9: =IF('1AS 1B'!K9="","", IF(ROUND('1AS 1B'!K9,0)<=10,"C", IF(ROUND('1AS 1B'!K9,0)<=13,"B", IF(ROUND('1AS 1B'!K9,0)<=17,"A", IF(ROUND('1AS 1B'!K9,0)<=20,"AD",""))))) -> A | ... AB9: =IF('1AS 1B'!AB9="","", IF(ROUND('1AS 1B'!AB9,0)<=10,"C", IF(ROUND('1AS 1B'!AB9,0)<=13,"B", IF(ROUND('1AS 1B'!AB9,0)<=17,"A", IF(ROUND('1AS 1B'!AB9,0)<=20,"AD",""))))) -> A | AD9: 15.78 | AE9: 142 | AG9: 12 | AH9: MED | AI9: 4 | AM9: =AE9+'1AS 2B'!AE9+'1AS 3B'!AE9+'1AS 4B'!AE9 -> 558 | AN9: =RANK(AM9,$AM$8:$AM$32, ) -> 9
A10: 3 | B10: BENITES ACOSTA, Cielo Guadalupe | D10: =IF('1AS 1B'!D10="","", IF(ROUND('1AS 1B'!D10,0)<=10,"C", IF(ROUND('1AS 1B'!D10,0)<=13,"B", IF(ROUND('1AS 1B'!D10,0)<=17,"A", IF(ROUND('1AS 1B'!D10,0)<=20,"AD",""))))) -> A | E10: =IF('1AS 1B'!E10="","", IF(ROUND('1AS 1B'!E10,0)<=10,"C", IF(ROUND('1AS 1B'!E10,0)<=13,"B", IF(ROUND('1AS 1B'!E10,0)<=17,"A", IF(ROUND('1AS 1B'!E10,0)<=20,"AD",""))))) -> A | F10: =IF('1AS 1B'!F10="","", IF(ROUND('1AS 1B'!F10,0)<=10,"C", IF(ROUND('1AS 1B'!F10,0)<=13,"B", IF(ROUND('1AS 1B'!F10,0)<=17,"A", IF(ROUND('1AS 1B'!F10,0)<=20,"AD",""))))) -> A | G10: =IF('1AS 1B'!G10="","", IF(ROUND('1AS 1B'!G10,0)<=10,"C", IF(ROUND('1AS 1B'!G10,0)<=13,"B", IF(ROUND('1AS 1B'!G10,0)<=17,"A", IF(ROUND('1AS 1B'!G10,0)<=20,"AD",""))))) -> A | H10: =IF('1AS 1B'!H10="","", IF(ROUND('1AS 1B'!H10,0)<=10,"C", IF(ROUND('1AS 1B'!H10,0)<=13,"B", IF(ROUND('1AS 1B'!H10,0)<=17,"A", IF(ROUND('1AS 1B'!H10,0)<=20,"AD",""))))) -> A | I10: =IF('1AS 1B'!I10="","", IF(ROUND('1AS 1B'!I10,0)<=10,"C", IF(ROUND('1AS 1B'!I10,0)<=13,"B", IF(ROUND('1AS 1B'!I10,0)<=17,"A", IF(ROUND('1AS 1B'!I10,0)<=20,"AD",""))))) -> A | J10: =IF('1AS 1B'!J10="","", IF(ROUND('1AS 1B'!J10,0)<=10,"C", IF(ROUND('1AS 1B'!J10,0)<=13,"B", IF(ROUND('1AS 1B'!J10,0)<=17,"A", IF(ROUND('1AS 1B'!J10,0)<=20,"AD",""))))) -> A | K10: =IF('1AS 1B'!K10="","", IF(ROUND('1AS 1B'!K10,0)<=10,"C", IF(ROUND('1AS 1B'!K10,0)<=13,"B", IF(ROUND('1AS 1B'!K10,0)<=17,"A", IF(ROUND('1AS 1B'!K10,0)<=20,"AD",""))))) -> B | ... AB10: =IF('1AS 1B'!AB10="","", IF(ROUND('1AS 1B'!AB10,0)<=10,"C", IF(ROUND('1AS 1B'!AB10,0)<=13,"B", IF(ROUND('1AS 1B'!AB10,0)<=17,"A", IF(ROUND('1AS 1B'!AB10,0)<=20,"AD",""))))) -> A | AD10: 14.33 | AE10: 129 | AG10: 23 | AH10: INF | AM10: =AE10+'1AS 2B'!AE10+'1AS 3B'!AE10+'1AS 4B'!AE10 -> 490 | AN10: =RANK(AM10,$AM$8:$AM$32, ) -> 25
A11: 4 | B11: CABANILLAS HUAYLLAHUA | D11: =IF('1AS 1B'!D11="","", IF(ROUND('1AS 1B'!D11,0)<=10,"C", IF(ROUND('1AS 1B'!D11,0)<=13,"B", IF(ROUND('1AS 1B'!D11,0)<=17,"A", IF(ROUND('1AS 1B'!D11,0)<=20,"AD",""))))) -> A | E11: =IF('1AS 1B'!E11="","", IF(ROUND('1AS 1B'!E11,0)<=10,"C", IF(ROUND('1AS 1B'!E11,0)<=13,"B", IF(ROUND('1AS 1B'!E11,0)<=17,"A", IF(ROUND('1AS 1B'!E11,0)<=20,"AD",""))))) -> A | F11: =IF('1AS 1B'!F11="","", IF(ROUND('1AS 1B'!F11,0)<=10,"C", IF(ROUND('1AS 1B'!F11,0)<=13,"B", IF(ROUND('1AS 1B'!F11,0)<=17,"A", IF(ROUND('1AS 1B'!F11,0)<=20,"AD",""))))) -> A | G11: =IF('1AS 1B'!G11="","", IF(ROUND('1AS 1B'!G11,0)<=10,"C", IF(ROUND('1AS 1B'!G11,0)<=13,"B", IF(ROUND('1AS 1B'!G11,0)<=17,"A", IF(ROUND('1AS 1B'!G11,0)<=20,"AD",""))))) -> A | H11: =IF('1AS 1B'!H11="","", IF(ROUND('1AS 1B'!H11,0)<=10,"C", IF(ROUND('1AS 1B'!H11,0)<=13,"B", IF(ROUND('1AS 1B'!H11,0)<=17,"A", IF(ROUND('1AS 1B'!H11,0)<=20,"AD",""))))) -> A | I11: =IF('1AS 1B'!I11="","", IF(ROUND('1AS 1B'!I11,0)<=10,"C", IF(ROUND('1AS 1B'!I11,0)<=13,"B", IF(ROUND('1AS 1B'!I11,0)<=17,"A", IF(ROUND('1AS 1B'!I11,0)<=20,"AD",""))))) -> A | J11: =IF('1AS 1B'!J11="","", IF(ROUND('1AS 1B'!J11,0)<=10,"C", IF(ROUND('1AS 1B'!J11,0)<=13,"B", IF(ROUND('1AS 1B'!J11,0)<=17,"A", IF(ROUND('1AS 1B'!J11,0)<=20,"AD",""))))) -> A | K11: =IF('1AS 1B'!K11="","", IF(ROUND('1AS 1B'!K11,0)<=10,"C", IF(ROUND('1AS 1B'!K11,0)<=13,"B", IF(ROUND('1AS 1B'!K11,0)<=17,"A", IF(ROUND('1AS 1B'!K11,0)<=20,"AD",""))))) -> A | ... AB11: =IF('1AS 1B'!AB11="","", IF(ROUND('1AS 1B'!AB11,0)<=10,"C", IF(ROUND('1AS 1B'!AB11,0)<=13,"B", IF(ROUND('1AS 1B'!AB11,0)<=17,"A", IF(ROUND('1AS 1B'!AB11,0)<=20,"AD",""))))) -> A | AD11: 15.89 | AE11: 143 | AG11: 8 | AH11: SUP | AI11: 1 | AM11: =AE11+'1AS 2B'!AE11+'1AS 3B'!AE11+'1AS 4B'!AE11 -> 555 | AN11: =RANK(AM11,$AM$8:$AM$32, ) -> 11
A12: 5 | B12: CENTENO TARAZONA, Camila Adriana | D12: =IF('1AS 1B'!D12="","", IF(ROUND('1AS 1B'!D12,0)<=10,"C", IF(ROUND('1AS 1B'!D12,0)<=13,"B", IF(ROUND('1AS 1B'!D12,0)<=17,"A", IF(ROUND('1AS 1B'!D12,0)<=20,"AD",""))))) -> A | E12: =IF('1AS 1B'!E12="","", IF(ROUND('1AS 1B'!E12,0)<=10,"C", IF(ROUND('1AS 1B'!E12,0)<=13,"B", IF(ROUND('1AS 1B'!E12,0)<=17,"A", IF(ROUND('1AS 1B'!E12,0)<=20,"AD",""))))) -> A | F12: =IF('1AS 1B'!F12="","", IF(ROUND('1AS 1B'!F12,0)<=10,"C", IF(ROUND('1AS 1B'!F12,0)<=13,"B", IF(ROUND('1AS 1B'!F12,0)<=17,"A", IF(ROUND('1AS 1B'!F12,0)<=20,"AD",""))))) -> A | G12: =IF('1AS 1B'!G12="","", IF(ROUND('1AS 1B'!G12,0)<=10,"C", IF(ROUND('1AS 1B'!G12,0)<=13,"B", IF(ROUND('1AS 1B'!G12,0)<=17,"A", IF(ROUND('1AS 1B'!G12,0)<=20,"AD",""))))) -> A | H12: =IF('1AS 1B'!H12="","", IF(ROUND('1AS 1B'!H12,0)<=10,"C", IF(ROUND('1AS 1B'!H12,0)<=13,"B", IF(ROUND('1AS 1B'!H12,0)<=17,"A", IF(ROUND('1AS 1B'!H12,0)<=20,"AD",""))))) -> A | I12: =IF('1AS 1B'!I12="","", IF(ROUND('1AS 1B'!I12,0)<=10,"C", IF(ROUND('1AS 1B'!I12,0)<=13,"B", IF(ROUND('1AS 1B'!I12,0)<=17,"A", IF(ROUND('1AS 1B'!I12,0)<=20,"AD",""))))) -> A | J12: =IF('1AS 1B'!J12="","", IF(ROUND('1AS 1B'!J12,0)<=10,"C", IF(ROUND('1AS 1B'!J12,0)<=13,"B", IF(ROUND('1AS 1B'!J12,0)<=17,"A", IF(ROUND('1AS 1B'!J12,0)<=20,"AD",""))))) -> A | K12: =IF('1AS 1B'!K12="","", IF(ROUND('1AS 1B'!K12,0)<=10,"C", IF(ROUND('1AS 1B'!K12,0)<=13,"B", IF(ROUND('1AS 1B'!K12,0)<=17,"A", IF(ROUND('1AS 1B'!K12,0)<=20,"AD",""))))) -> A | ... AB12: =IF('1AS 1B'!AB12="","", IF(ROUND('1AS 1B'!AB12,0)<=10,"C", IF(ROUND('1AS 1B'!AB12,0)<=13,"B", IF(ROUND('1AS 1B'!AB12,0)<=17,"A", IF(ROUND('1AS 1B'!AB12,0)<=20,"AD",""))))) -> A | AD12: 16.11 | AE12: 145 | AG12: 5 | AH12: SUP | AM12: =AE12+'1AS 2B'!AE12+'1AS 3B'!AE12+'1AS 4B'!AE12 -> 578 | AN12: =RANK(AM12,$AM$8:$AM$32, ) -> 5
A13: 6 | B13: CHAHUARES HUAMANI, Lucero Andrea | D13: =IF('1AS 1B'!D13="","", IF(ROUND('1AS 1B'!D13,0)<=10,"C", IF(ROUND('1AS 1B'!D13,0)<=13,"B", IF(ROUND('1AS 1B'!D13,0)<=17,"A", IF(ROUND('1AS 1B'!D13,0)<=20,"AD",""))))) -> A | E13: =IF('1AS 1B'!E13="","", IF(ROUND('1AS 1B'!E13,0)<=10,"C", IF(ROUND('1AS 1B'!E13,0)<=13,"B", IF(ROUND('1AS 1B'!E13,0)<=17,"A", IF(ROUND('1AS 1B'!E13,0)<=20,"AD",""))))) -> A | F13: =IF('1AS 1B'!F13="","", IF(ROUND('1AS 1B'!F13,0)<=10,"C", IF(ROUND('1AS 1B'!F13,0)<=13,"B", IF(ROUND('1AS 1B'!F13,0)<=17,"A", IF(ROUND('1AS 1B'!F13,0)<=20,"AD",""))))) -> A | G13: =IF('1AS 1B'!G13="","", IF(ROUND('1AS 1B'!G13,0)<=10,"C", IF(ROUND('1AS 1B'!G13,0)<=13,"B", IF(ROUND('1AS 1B'!G13,0)<=17,"A", IF(ROUND('1AS 1B'!G13,0)<=20,"AD",""))))) -> A | H13: =IF('1AS 1B'!H13="","", IF(ROUND('1AS 1B'!H13,0)<=10,"C", IF(ROUND('1AS 1B'!H13,0)<=13,"B", IF(ROUND('1AS 1B'!H13,0)<=17,"A", IF(ROUND('1AS 1B'!H13,0)<=20,"AD",""))))) -> A | I13: =IF('1AS 1B'!I13="","", IF(ROUND('1AS 1B'!I13,0)<=10,"C", IF(ROUND('1AS 1B'!I13,0)<=13,"B", IF(ROUND('1AS 1B'!I13,0)<=17,"A", IF(ROUND('1AS 1B'!I13,0)<=20,"AD",""))))) -> A | J13: =IF('1AS 1B'!J13="","", IF(ROUND('1AS 1B'!J13,0)<=10,"C", IF(ROUND('1AS 1B'!J13,0)<=13,"B", IF(ROUND('1AS 1B'!J13,0)<=17,"A", IF(ROUND('1AS 1B'!J13,0)<=20,"AD",""))))) -> A | K13: =IF('1AS 1B'!K13="","", IF(ROUND('1AS 1B'!K13,0)<=10,"C", IF(ROUND('1AS 1B'!K13,0)<=13,"B", IF(ROUND('1AS 1B'!K13,0)<=17,"A", IF(ROUND('1AS 1B'!K13,0)<=20,"AD",""))))) -> A | ... AB13: =IF('1AS 1B'!AB13="","", IF(ROUND('1AS 1B'!AB13,0)<=10,"C", IF(ROUND('1AS 1B'!AB13,0)<=13,"B", IF(ROUND('1AS 1B'!AB13,0)<=17,"A", IF(ROUND('1AS 1B'!AB13,0)<=20,"AD",""))))) -> A | AD13: 15.89 | AE13: 143 | AG13: 8 | AH13: SUP | AI13: 1 | AM13: =AE13+'1AS 2B'!AE13+'1AS 3B'!AE13+'1AS 4B'!AE13 -> 562 | AN13: =RANK(AM13,$AM$8:$AM$32, ) -> 8
